Workbook

Sheet Overall - Top sheet
A1: QUEEN MIRA INTERNATIONAL SCHOOL
A2: TOP SHEET - SALARY STATEMENT FEBRUARY 2026
A3: S. No | B3: Particulars | C3: No of Employees | D3: Gross Salary ( A ) | E3: Average Salary | F3: Deductions | L3: Net Salary [D] | M3: Employer Contribution | O3: Total [A+E+F]
F4: Late / Permission / Leave / Absent LOP | G4: Not Punched LOP | H4: Salary Advance / Loan | I4: Special Deductions [Telephone Bill + Laptop + Uniform + Trainings etc] | J4: PF 12% [B] | K4: ESI 0.75% [C] | M4: PF 13.01% [E] | N4: ESI 3.25% [F]
A5: 1 | B5: Academics Staff | C5: =Academics!#REF! -> #REF! | D5: =Academics!V10+Academics!X10 -> 230500 | E5: =D5/C5 -> #REF! | F5: =Academics!AB10 -> 1428.5714 | G5: =Academics!AD10 -> 0 | H5: =Academics!AE10 -> 0 | I5: =Academics!AF10 -> 299 | J5: =Academics!AG10 -> 4176 | K5: =Academics!AH10 -> 0 | L5: =Academics!AJ10 -> 224596 | M5: =Academics!AK10 -> 4527.48 | N5: =Academics!AL10 -> 0 | O5: =D5+M5+N5 -> 235027.48
A6: 2 | B6: Admin Staff | C6: =Admin!#REF! -> #REF! | D6: =Admin!V11+Admin!X11 -> 271000 | E6: =D6/C6 -> #REF! | F6: =Admin!AB11 -> 9642.8571 | G6: =Admin!AD11 -> 0 | H6: =Admin!AE11 -> 10000 | I6: =Admin!AF11 -> 299 | J6: =Admin!AG11 -> 2880 | K6: =Admin!AH11 -> 142 | L6: =Admin!AJ11 -> 248037 | M6: =Admin!AK11 -> 3122.4 | N6: =Admin!AL11 -> 616 | O6: =D6+M6+N6 -> 274738.4
A7: 3 | B7: Drivers | C7: 17 | D7: =Drivers!V9 -> 86300 | E7: =D7/C7 -> 5076.4706 | F7: =Drivers!AB9 -> 23200 | G7: =Drivers!AD9 -> 0 | H7: =Drivers!AE9 -> 0 | I7: =Drivers!AF9 -> 0 | J7: =Drivers!AG9 -> 3409 | K7: =Drivers!AH9 -> 313 | L7: =Drivers!AJ9 -> 59378 | M7: =Drivers!AK9 -> 3695 | N7: =Drivers!AL9 -> 1356 | O7: =D7+M7+N7 -> 91351
A8: 4 | B8: Conductors | C8: =+Conductors!#REF! -> #REF! | D8: =Conductors!W10+Conductors!X10 -> 51300 | E8: =D8/C8 -> #REF! | F8: =Conductors!AB10 -> 9075 | G8: =Conductors!AD10 -> 0 | H8: =Conductors!AE10 -> 0 | I8: =Conductors!AF10 -> 0 | J8: =Conductors!AG10 -> 1821 | K8: =Conductors!AH10 -> 186 | L8: =Conductors!AJ10 -> 40218 | M8: =Conductors!AK10 -> 1974 | N8: =Conductors!AL10 -> 802 | O8: =D8+M8+N8 -> 54076
A9: 5 | B9: Securities | C9: =+Securities!#REF! -> #REF! | D9: =Securities!V8+Securities!X8 -> 56000 | E9: =D9/C9 -> #REF! | F9: =Securities!AB8 -> 405.35714 | G9: =Securities!AD8 -> 0 | H9: =Securities!AE8 -> 10000 | I9: =Securities!AF8 -> 0 | J9: =Securities!AG8 -> 0 | K9: =Securities!AH8 -> 0 | L9: =Securities!AJ8 -> 45595 | M9: =Securities!AK8 -> 0 | N9: =Securities!AL8 -> 0 | O9: =D9+M9+N9 -> 56000
A10: 6 | B10: Housekeeping | C10: 17 | D10: ='House Keeping'!V9 -> 49100 | E10: =D10/C10 -> 2888.2353 | F10: ='House Keeping'!AB9 -> 6869.6429 | G10: ='House Keeping'!AD9 -> 0 | H10: ='House Keeping'!AE9 -> 3000 | I10: ='House Keeping'!AF9 -> 0 | J10: ='House Keeping'!AG9 -> 1772 | K10: ='House Keeping'!AH9 -> 318 | L10: ='House Keeping'!AJ9 -> 37140 | M10: ='House Keeping'!AK9 -> 1921 | N10: ='House Keeping'!AL9 -> 1374 | O10: =D10+M10+N10 -> 52395
A11: 7 | B11: Hostel | C11: =+Hostel!A7 -> 3 | D11: =Hostel!V8 -> 38000 | E11: =D11/C11 -> 12666.667 | F11: =Hostel!AB8 -> 250 | G11: =Hostel!AD8 -> 0 | H11: =Hostel!AE8 -> 0 | I11: =Hostel!AF8 -> 0 | J11: =Hostel!AG8 -> 0 | K11: =Hostel!AH8 -> 0 | L11: =Hostel!AJ8 -> 37750 | M11: =Hostel!AK8 -> 0 | N11: =Hostel!AL8 -> 0 | O11: =D11+M11+N11 -> 38000
A12: 8 | B12: ECA - Regular | C12: =+'ECA - Regular'!#REF! -> #REF! | D12: ='ECA - Regular'!D9 -> 53400 | E12: =D12/C12 -> #REF! | F12: ='ECA - Regular'!K9 -> 4500 | H12: ='ECA - Regular'!J9 -> 0 | I12: ='ECA - Regular'!L9 -> 0 | L12: ='ECA - Regular'!M9 -> 48900 | O12: =D12+M12+N12 -> 53400
A13: 9 | B13: Part Time - Academics | C13: =+' Part Time - Academics'!A8 -> 5 | D13: =' Part Time - Academics'!D9+' Part Time - Academics'!E9 -> 133550 | E13: =D13/C13 -> 26710 | F13: =' Part Time - Academics'!M9 -> 0 | H13: =' Part Time - Academics'!I9 -> 0 | I13: =' Part Time - Academics'!L9 -> 0 | L13: =' Part Time - Academics'!O9 -> 133550 | O13: =D13+M13+N13 -> 133550
A14: 10 | B14: Academics + ECA = Special | C14: =+'Aca +ECA = Spl'!#REF! -> #REF! | D14: ='Aca +ECA = Spl'!D9 -> 151825 | E14: =D14/C14 -> #REF! | F14: ='Aca +ECA = Spl'!I9 -> 0 | I14: ='Aca +ECA = Spl'!H9 -> 0 | L14: ='Aca +ECA = Spl'!J9 -> 151825 | O14: =D14+M14+N14 -> 151825
A15: 11 | B15: Theni Upparpatti | C15: =+'Theni - Upparpatti'!A8 -> 4 | D15: ='Theni - Upparpatti'!V9 -> 34000 | E15: =D15/C15 -> 8500 | F15: ='Theni - Upparpatti'!AB9 -> 535.71429 | G15: ='Theni - Upparpatti'!AD9 -> 0 | H15: ='Theni - Upparpatti'!AE9 -> 0 | I15: ='Theni - Upparpatti'!AF9 -> 0 | J15: ='Theni - Upparpatti'!AG9 -> 0 | K15: ='Theni - Upparpatti'!AH9 -> 0 | L15: ='Theni - Upparpatti'!AJ9 -> 33464 | M15: ='Theni - Upparpatti'!AK9 -> 0 | N15: ='Theni - Upparpatti'!AL9 -> 0 | O15: =D15+M15+N15 -> 34000
A16: 12 | B16: Academic Enrichment Program | C16: =+AEP!A9 -> 6 | D16: =AEP!I10 -> 38050 | E16: =D16/C16 -> 6341.6667 | F16: =AEP!G10 -> 0 | I16: =AEP!F10 -> 0 | L16: =AEP!I10 -> 38050 | O16: =D16+M16+N16 -> 38050
A17: 13 | B17: Rifle Shooting | C17: =Rifle!A4 -> 1 | D17: =Rifle!D5 -> 60000 | E17: =D17/C17 -> 60000 | F17: =Rifle!J5 -> 0 | H17: =Rifle!H5 -> 0 | I17: =Rifle!F5 -> 0 | L17: =Rifle!L5 -> 60000 | O17: =D17+M17+N17 -> 60000
A18: 14 | B18: Part Time Admin | C18: ='Part Time - Admin'!A5 -> 2 | D18: ='Part Time - Admin'!D6 -> 38382.857 | E18: =D18/C18 -> 19191.429 | F18: ='Part Time - Admin'!L6 -> 0 | H18: 0 | I18: ='Part Time - Admin'!K6 -> 0 | L18: ='Part Time - Admin'!N6 -> 38383 | O18: =D18+M18+N18 -> 38382.857
A19: 15 | B19: Relieved Academics | C19: =+'Relieved Academics'!A5 -> 1 | D19: ='Relieved Academics'!V6 -> 7000 | E19: 0 | F19: ='Relieved Academics'!AB6 -> 673.07692 | G19: ='Relieved Academics'!AD6 -> 0 | H19: ='Relieved Academics'!AE6 -> 0 | I19: ='Relieved Academics'!AF6 -> 0 | J19: ='Relieved Academics'!AG6 -> 0 | K19: ='Relieved Academics'!AH6 -> 0 | L19: =+'Relieved Academics'!AJ7 -> 0 | M19: ='Relieved Academics'!AK6 -> 0 | N19: ='Relieved Academics'!AL6 -> 0 | O19: =D19+M19+N19 -> 7000
A20: 16 | B20: Relieved Admin | C20: 7 | D20: ='Relieved Admin'!V12 -> 112000 | E20: 0 | F20: ='Relieved Admin'!AB12 -> 1928.5714 | G20: ='Relieved Admin'!E12 -> 0 | H20: ='Relieved Admin'!AE12 -> 0 | I20: ='Relieved Admin'!AF12 -> 3353 | J20: ='Relieved Admin'!AG12 -> 0 | K20: ='Relieved Admin'!AH12 -> 0 | L20: ='Relieved Admin'!AJ13 -> 29814 | M20: ='Relieved Admin'!AK12 -> 0 | N20: ='Relieved Admin'!AL12 -> 0 | O20: =D20+M20+N20 -> 112000
A21: Total | C21: =+C5+C6+C7+C8+C9+C10+2+9+5+10+3+1+2 -> #REF! | D21: =SUM(D5:D20) -> 1410407.9 | E21: =SUM(E5:E20) -> #REF! | F21: =SUM(F5:F20) -> 58508.791 | G21: =SUM(G5:G20) -> 0 | H21: =SUM(H5:H20) -> 23000 | I21: =SUM(I5:I20) -> 3951 | J21: =SUM(J5:J20) -> 14058 | K21: =SUM(K5:K20) -> 959 | ... O21: =SUM(O5:O20) -> 1429795.7
A23: Payable Total (B+C+D+E+F) | O23: =J21+K21+L21+M21+N21 -> 1261104.9
A24: HR Manager | C24: Finance Manager | F24: Joint Director Admin | J24: Director Academics | N24: Managing Director

Sheet Academics
A1: QUEEN MIRA INTERNATIONAL SCHOOL
A2: ACADEMICS - SALARY STATEMENT FEBRUARY 2026
A3: S.No | B3: Name | C3: Department | D3: Attendance | R3: Salary Advance / Loan Details | V3: Gross Salary | W3: Payable Gross Salary | X3: Other Allownace | Y3: Salary.Actuals [Gross Salary - Leave Deduction] | Z3: Salary per day [Gross salary / no of days that month] | AA3: Basic [45% of Gross Salary] | AB3: Deductions | AJ3: Net Salary | AK3: QMIS Contribution | AM3: Remarks
D4: Total working days | E4: Lates. Actuals | F4: Lates. Leave [Exceeding lates conversions count] | G4: Final Lates after deducting exceeding Late leaves | H4: Permissions.Actuals | I4: Exceeding Permissions taken for this month | J4: Proper Permissions | K4: Proper Casual Leave already taken for this year till date | L4: Proper Casual Leave taken for this month | M4: Exceeding Casual Leave taken for this month / Memo issued | N4: Absent / Suspension.Actuals | O4: Gardening / Other Leave | P4: Total Leave days.Actuals | Q4: Loss of Pay Days | R4: Total Loan Amount | S4: Amount already paid | T4: Amount to be paid for this month | U4: Remaining Loan Amount | AB4: Leave / Absent / Permission Leave / Late Leave | AC4: Not Punched Days | AD4: Not Punched LOP | AE4: Salary Advance / Loan | AF4: Special Deductions [Telephone Bill + healthcheck up + Uniform + Trainings etc] | AG4: PF [12% of Basic Salary] | AH4: ESI [0.75% of Salary.Actuals] | AI4: Total | AK4: PF [13.01% of Basic Salary] | AL4: ESI [3.25% of Salary.Actuals]
A5: 1 | B5: SUJATHA D/O SUBBURAM | C5: Director - Academics | D5: 28 | E5: 0 | F5: =IF((E5/3)>=1,TRUNC(E5/3,0),0) -> 0 | G5: =E5-F5*3 -> 0 | H5: 0 | I5: =IF(H5<1,H5,H5-1) -> 0 | J5: =H5-I5 -> 0 | K5: =0+3+0.5 -> 3.5 | L5: 0 | M5: 0 | N5: 0 | O5: 0 | P5: =L5+M5+N5+O5 -> 0 | Q5: =(F5*0.5)+(I5*0.5)+M5+(N5*2) -> 0 | R5: 0 | S5: 0 | T5: 0 | U5: =R5-(S5+T5) -> 0 | V5: 105000 | W5: =V5 -> 105000 | X5: 0 | Y5: =W5-AB5 -> 105000 | Z5: =V5/D5 -> 3750 | AA5: 15000 | AB5: =Q5*Z5 -> 0 | AD5: =(AC5)*Z5 -> 0 | AE5: =T5 -> 0 | AG5: =(AA5*12%) -> 1800 | AH5: 0 | AI5: =SUM(AB5,AD5:AH5) -> 1800 | AJ5: =ROUND(SUM(W5:X5)-AI5,0) -> 103200 | AK5: =(AA5*13.01%) -> 1951.5 | AL5: 0 | AN5: 1750155000050628
A6: 2 | B6: A JAINCOL FATHIMA | C6: Assistant Vice Principal Kinder Garten / PRT-English | D6: 28 | E6: 3 | F6: =IF((E6/3)>=1,TRUNC(E6/3,0),0) -> 1 | G6: =E6-F6*3 -> 0 | H6: 0 | I6: =IF(H6<1,H6,H6-1) -> 0 | J6: =H6-I6 -> 0 | K6: =3+1.5+0 -> 4.5 | L6: 1 | M6: 0 | N6: 0 | O6: 0 | P6: =L6+M6+N6+O6 -> 1 | Q6: =(F6*0.5)+(I6*0.5)+M6+(N6*2) -> 0.5 | R6: 0 | S6: 0 | T6: 0 | U6: =R6-(S6+T6) -> 0 | V6: 36000 | W6: =V6 -> 36000 | X6: 5000 | Y6: =W6-AB6 -> 35357.143 | Z6: =V6/D6 -> 1285.7143 | AA6: =W6*45% -> 16200 | AB6: =Q6*Z6 -> 642.85714 | AC6: 0 | AD6: =(AC6)*Z6 -> 0 | AE6: =T6 -> 0 | AF6: =299 -> 299 | AG6: 0 | AH6: 0 | AI6: =SUM(AB6,AD6:AH6) -> 941.85714 | AJ6: =ROUND(SUM(W6:X6)-AI6,0) -> 40058 | AK6: 0 | AL6: 0 | AM6: 5000 - For handling Grade 2 and 3 english. | AN6: 1750061000000064
A7: 3 | B7: GAYATHRI MURUGAN | C7: Coordinator (Gr6-8)/ SGT - Maths | D7: 28 | E7: 0 | F7: =IF((E7/3)>=1,TRUNC(E7/3,0),0) -> 0 | G7: =E7-F7*3 -> 0 | H7: 0 | I7: =IF(H7<1,H7,H7-1) -> 0 | J7: =H7-I7 -> 0 | K7: =3+3+1 -> 7 | L7: 1 | M7: 0 | N7: 0 | O7: 0 | P7: =L7+M7+N7+O7 -> 1 | Q7: =(F7*0.5)+(I7*0.5)+M7+(N7*2) -> 0 | R7: 0 | S7: 0 | T7: 0 | U7: =R7-(S7+T7) -> 0 | V7: 34500 | W7: =V7 -> 34500 | X7: 6000 | Y7: =W7-AB7 -> 34500 | Z7: =V7/D7 -> 1232.1429 | AA7: =W7*45% -> 15525 | AB7: =Q7*Z7 -> 0 | AD7: =(AC7)*Z7 -> 0 | AE7: =T7 -> 0 | AG7: 0 | AH7: 0 | AI7: =SUM(AB7,AD7:AH7) -> 0 | AJ7: =ROUND(SUM(W7:X7)-AI7,0) -> 40500 | AK7: 0 | AL7: 0 | AM7: 6000 - For handling Grade 1 maths from October 2025 | AN7: 1750061000000102
A8: 4 | B8: GOWSALYA DEVI BALAMURUGAN | C8: Facilitator(KG)/ Nursery Trained Teacher | D8: 28 | E8: 2 | F8: =IF((E8/3)>=1,TRUNC(E8/3,0),0) -> 0 | G8: =E8-F8*3 -> 2 | H8: 2 | I8: =IF(H8<1,H8,H8-1) -> 1 | J8: =H8-I8 -> 1 | K8: =3+2+0 -> 5 | L8: 1 | M8: 0 | N8: 0 | O8: 0 | P8: =L8+M8+N8+O8 -> 1 | Q8: =(F8*0.5)+(I8*0.5)+M8+(N8*2) -> 0.5 | R8: 0 | S8: 0 | T8: 0 | U8: =R8-(S8+T8) -> 0 | V8: 23000 | W8: =V8 -> 23000 | X8: 0 | Y8: =W8-AB8 -> 22589.286 | Z8: =V8/D8 -> 821.42857 | AA8: =W8*45% -> 10350 | AB8: =Q8*Z8 -> 410.71429 | AD8: =(AC8)*Z8 -> 0 | AE8: =T8 -> 0 | AG8: =(AA8*12%) -> 1242 | AH8: 0 | AI8: =SUM(AB8,AD8:AH8) -> 1652.7143 | AJ8: =ROUND(SUM(W8:X8)-AI8,0) -> 21347 | AK8: =(AA8*13.01%) -> 1346.535 | AL8: 0 | AN8: 1750060000000791
A9: 5 | B9: P JAGATHESWARI | C9: PRT-Science | D9: 28 | E9: 4 | F9: =IF((E9/3)>=1,TRUNC(E9/3,0),0) -> 1 | G9: =E9-F9*3 -> 1 | H9: 0 | I9: =IF(H9<1,H9,H9-1) -> 0 | J9: =H9-I9 -> 0 | K9: =1.5+2+1.5 -> 5 | L9: 1 | M9: 0 | N9: 0 | O9: 0 | P9: =L9+M9+N9+O9 -> 1 | Q9: =(F9*0.5)+(I9*0.5)+M9+(N9*2) -> 0.5 | R9: 0 | S9: 0 | T9: 0 | U9: =R9-(S9+T9) -> 0 | V9: 21000 | W9: =V9 -> 21000 | X9: 0 | Y9: =W9-AB9 -> 20625 | Z9: =V9/D9 -> 750 | AA9: =W9*45% -> 9450 | AB9: =Q9*Z9 -> 375 | AD9: =(AC9)*Z9 -> 0 | AE9: =T9 -> 0 | AG9: =(AA9*12%) -> 1134 | AH9: 0 | AI9: =SUM(AB9,AD9:AH9) -> 1509 | AJ9: =ROUND(SUM(W9:X9)-AI9,0) -> 19491 | AK9: =(AA9*13.01%) -> 1229.445 | AL9: 0 | AN9: 1750060000000153
R10: =SUM(R5:R9) -> 0 | S10: =SUM(S5:S9) -> 0 | T10: =SUM(T5:T9) -> 0 | U10: =SUM(U5:U9) -> 0 | V10: =SUM(V5:V9) -> 219500 | W10: =SUM(W5:W9) -> 219500 | X10: =SUM(X5:X9) -> 11000 | Y10: =SUM(Y5:Y9) -> 218071.43 | ... AD10: =SUM(AD5:AD9) -> 0 | AE10: =T10 -> 0 | AF10: =SUM(AF5:AF9) -> 299 | AG10: =SUM(AG5:AG9) -> 4176 | AH10: =SUM(AH5:AH9) -> 0 | AI10: =SUM(AI5:AI9) -> 5903.5714 | AJ10: =SUM(AJ5:AJ9) -> 224596 | AK10: =SUM(AK5:AK9) -> 4527.48 | AL10: =SUM(AL5:AL9) -> 0 | AM10: =SUM(AM5:AM9) -> 0
A11: HR Manager | W11: Director Academics | AL11: Finance Manager

Sheet Relieved Academics
A1: QUEEN MIRA INTERNATIONAL SCHOOL
A2: ACADEMICS RELIEVED- SALARY STATEMENT FEBRUARY 2026
A3: S.No | B3: Name | C3: Department | D3: Attendance | R3: Salary Advance / Loan Details | V3: Gross Salary | W3: Payable Gross Salary | X3: Other Allowance | Y3: Salary. Actuals [Gross Salary - Leave Deduction] | Z3: Salary per day [Gross salary / no of days that month] | AA3: Basic [45% of Gross Salary] | AB3: Deductions | AJ3: Net Salary | AK3: QMIS Contribution | AM3: Remarks
D4: Total working days | E4: Lates. Actuals | F4: Lates. Leave [Exceeding lates conversions count] | G4: Final Lates after deducting exceeding Late leaves | H4: Permissions. Actuals | I4: Exceeding Permissions taken for this month | J4: Proper Permissions | K4: Proper Casual Leave already taken for this year till date | L4: Proper Casual Leave taken for this month | M4: Exceeding Casual Leave taken for this month | N4: Absent / Suspension. Actuals | O4: Gardening / Other Leave | P4: Total Leave days. Actuals | Q4: Loss of Pay Days | R4: Total Loan Amount | S4: Amount already paid | T4: Amount to be paid for this month | U4: Remaining Loan Amount | AB4: Leave / Absent / Permission Leave / Late Leave | AC4: Not Punched Days | AD4: Not Punched LOP | AE4: Salary Advance / Loan | AF4: Special Deductions [Telephone Bill + Laptop + Uniform + Trainings etc] | AG4: PF [12% of Basic Salary] | AH4: ESI [0.75% of Salary. Actuals] | AI4: Total | AK4: PF [13.01% of Basic Salary] | AL4: ESI [3.25% of Salary. Actuals]
A5: 1 | B5: Akshaya Shree | C5: Nursery Trained Teacher Intern | D5: 26 | E5: 2 | F5: =IF((E5/3)>=1,TRUNC(E5/3,0),0) -> 0 | G5: =E5-F5*3 -> 2 | H5: 0 | I5: =IF(H5<1,H5,H5-1) -> 0 | J5: =H5-I5 -> 0 | K5: 0 | L5: 1 | M5: 2.5 | N5: 0 | O5: 0 | P5: =L5+M5+N5+O5 -> 3.5 | Q5: =(F5*0.5)+(I5*0.5)+M5+(N5*2) -> 2.5 | U5: =R5-(S5+T5) -> 0 | V5: 7000 | W5: =V5/28*26 -> 6500 | Y5: =W5-AB5 -> 5826.9231 | Z5: =V5/D5 -> 269.23077 | AA5: =W5*45% -> 2925 | AB5: =Q5*Z5 -> 673.07692 | AD5: =(AC5)*Z5 -> 0 | AE5: =T5 -> 0 | AF5: 0 | AG5: 0 | AH5: 0 | AI5: =SUM(AB5,AD5:AH5) -> 673.07692 | AJ5: =ROUND(SUM(W5:X5)-AI5,0) -> 5827 | AM5: DOJ : 02.02.2026. Gross Salary : Rs 7,000 (March and April). Dropped her resignation on 28.02.2026. DA instruction to witheld the salary.
A6: TOTAL | R6: =R5 -> 0 | S6: =S5 -> 0 | T6: =T5 -> 0 | U6: =U5 -> 0 | V6: =V5 -> 7000 | W6: =W5 -> 6500 | X6: =X5 -> 0 | Y6: =Y5 -> 5826.9231 | ... AL6: =AL5 -> 0
AD7: Payable salary | AJ7: 0
A8: HR Manager | U8: Director Academics | AK8: Finance Manager

Sheet Admin
A1: QUEEN MIRA INTERNATIONAL SCHOOL
A2: ADMIN - SALARY STATEMENT FEBRUARY 2026
A3: S.No | B3: Name | C3: Department | D3: Attendance | R3: Salary Advance / Loan Details | V3: Gross Salary | W3: Payable Gross Salary | X3: Other Allownace | Y3: Salary.Actuals [Gross Salary - Leave Deduction] | Z3: Salary per day [Gross salary / no of days that month] | AA3: Basic [45% of Gross Salary] | AB3: Deductions | AJ3: Net Salary | AK3: QMIS Contribution | AM3: Remarks
D4: Total working days | E4: Lates. Actuals | F4: Lates. Leave [Exceeding lates conversions count] | G4: Final Lates after deducting exceeding Late leaves | H4: Permissions.Actuals | I4: Exceeding Permissions taken for this month | J4: Proper Permissions | K4: Proper Casual Leave already taken for this year till date | L4: Proper Casual Leave taken for this month | M4: Exceeding Casual Leave taken for this month / Memo issued | N4: Absent / Suspension.Actuals | O4: Gardening / Other Leave | P4: Total Leave days.Actuals | Q4: Loss of Pay Days | R4: Total Loan Amount | S4: Amount already paid | T4: Amount to be paid for this month | U4: Remaining Loan Amount | AB4: Leave / Absent / Permission Leave / Late Leave | AC4: Not Punched Days | AD4: Not Punched LOP | AE4: Salary Advance / Loan | AF4: Special Deductions [Telephone Bill + healthcheck up + Uniform + Trainings etc] | AG4: PF [12% of Basic Salary] | AH4: ESI [0.75% of Salary.Actuals] | AI4: Total | AK4: PF [13.01% of Basic Salary] | AL4: ESI [3.25% of Salary.Actuals]
A5: 1 | B5: JOSEPHINE ANNE SHEEBHA ARULDASS | C5: Joint Director- Admin | D5: 28 | E5: 0 | F5: =IF((E5/3)>=1,TRUNC(E5/3,0),0) -> 0 | G5: =E5-F5*3 -> 0 | H5: 0 | I5: =IF(H5<1,H5,H5-1) -> 0 | J5: =H5-I5 -> 0 | K5: =3+0+3 -> 6 | L5: 0 | M5: 0 | N5: 0 | O5: 0 | P5: =L5+M5+N5+O5 -> 0 | Q5: =(F5*0.5)+(I5*0.5)+M5+(N5*2) -> 0 | R5: 100000 | S5: =10000+10000+10000+10000+10000+10000+10000 -> 70000 | T5: 10000 | U5: =R5-(S5+T5) -> 20000 | V5: 85000 | W5: =V5 -> 85000 | X5: 0 | Y5: =W5-AB5 -> 85000 | Z5: =V5/D5 -> 3035.7143 | AA5: 15000 | AB5: =Q5*Z5 -> 0 | AD5: =(AC5)*Z5 -> 0 | AE5: =T5 -> 10000 | AG5: =(AA5*12%) -> 1800 | AH5: 0 | AI5: =SUM(AB5,AD5:AH5) -> 11800 | AJ5: =ROUND(SUM(W5:X5)-AI5,0) -> 73200 | AK5: =(AA5*13.01%) -> 1951.5 | AL5: 0 | AM5: 5,000 will be given as cash. Salary Adv Note :4 Pg No. 19 | AN5: 1750062000000072
A6: 2 | B6: Jeya Dharini Abinath | C6: GM - Finance | D6: 28 | E6: 0 | F6: =IF((E6/3)>=1,TRUNC(E6/3,0),0) -> 0 | G6: =E6-F6*3 -> 0 | H6: 0 | I6: =IF(H6<1,H6,H6-1) -> 0 | J6: =H6-I6 -> 0 | K6: 0 | L6: 0 | M6: 0 | N6: 0 | O6: 0 | P6: =L6+M6+N6+O6 -> 0 | Q6: =(F6*0.5)+(I6*0.5)+M6+(N6*2) -> 0 | U6: =R6-(S6+T6) -> 0 | V6: 25000 | W6: =V6 -> 25000 | X6: 0 | Y6: =W6-AB6 -> 25000 | Z6: =V6/D6 -> 892.85714 | AA6: =W6*45% -> 11250 | AB6: =Q6*Z6 -> 0 | AD6: =(AC6)*Z6 -> 0 | AE6: =T6 -> 0 | AG6: 0 | AH6: 0 | AI6: =SUM(AB6,AD6:AH6) -> 0 | AJ6: =ROUND(SUM(W6:X6)-AI6,0) -> 25000 | AK6: 0 | AL6: 0
A7: 3 | B7: Ashrafa | C7: Joint Director - Audit | D7: 28 | E7: 0 | F7: =IF((E7/3)>=1,TRUNC(E7/3,0),0) -> 0 | G7: =E7-F7*3 -> 0 | H7: 0 | I7: =IF(H7<1,H7,H7-1) -> 0 | J7: =H7-I7 -> 0 | K7: 0 | L7: 0 | M7: 0 | N7: 0 | O7: 0 | P7: =L7+M7+N7+O7 -> 0 | Q7: =(F7*0.5)+(I7*0.5)+M7+(N7*2) -> 0 | U7: =R7-(S7+T7) -> 0 | V7: 75000 | W7: =V7 -> 75000 | X7: 0 | Y7: =W7-AB7 -> 75000 | Z7: =V7/D7 -> 2678.5714 | AA7: =W7*45% -> 33750 | AB7: =Q7*Z7 -> 0 | AD7: =(AC7)*Z7 -> 0 | AE7: =T7 -> 0 | AF7: 0 | AG7: 0 | AH7: 0 | AI7: =SUM(AB7,AD7:AH7) -> 0 | AJ7: =ROUND(SUM(W7:X7)-AI7,0) -> 75000 | AK7: 0 | AL7: 0
A8: 4 | B8: SHALINI NAGENDRA BABU | C8: Executive Assistant to JD Admin | D8: 28 | E8: 15 | F8: =IF((E8/3)>=1,TRUNC(E8/3,0),0) -> 5 | G8: =E8-F8*3 -> 0 | H8: 0 | I8: =IF(H8<1,H8,H8-1) -> 0 | J8: =H8-I8 -> 0 | K8: =2.5+4+1.5 -> 8 | L8: 1 | M8: 5 | N8: 0 | O8: 0 | P8: =L8+M8+N8+O8 -> 6 | Q8: =(F8*0.5)+(I8*0.5)+M8+(N8*2) -> 7.5 | V8: 32000 | W8: =V8 -> 32000 | X8: 0 | Y8: =W8-AB8 -> 23428.571 | Z8: =V8/D8 -> 1142.8571 | AA8: =W8*45% -> 14400 | AB8: =Q8*Z8 -> 8571.4286 | AD8: =(AC8)*Z8 -> 0 | AE8: =T8 -> 0 | AF8: =299 -> 299 | AG8: 0 | AH8: 0 | AI8: =SUM(AB8,AD8:AH8) -> 8870.4286 | AJ8: =ROUND(SUM(W8:X8)-AI8,0) -> 23130 | AK8: 0 | AL8: 0 | AM8: 2 lates considered for late closure. 5 days considered exceeding CL as per MD's instrucction(She was not allowed to report to the school) | AN8: 1.750061e+15
A9: 5 | B9: G VAIYAPURI | C9: Public Relations Officer | D9: 28 | E9: 0 | F9: =IF((E9/3)>=1,TRUNC(E9/3,0),0) -> 0 | G9: =E9-F9*3 -> 0 | H9: 0 | I9: =IF(H9<1,H9,H9-1) -> 0 | J9: =H9-I9 -> 0 | K9: =5+2.5+4.5 -> 12 | L9: 1 | M9: 0 | N9: 0 | O9: 0 | P9: =L9+M9+N9+O9 -> 1 | Q9: =(F9*0.5)+(I9*0.5)+M9+(N9*2) -> 0 | U9: =R9-(S9+T9) -> 0 | V9: 34000 | W9: =V9 -> 34000 | X9: 0 | Y9: =W9-AB9 -> 34000 | Z9: =V9/D9 -> 1214.2857 | AA9: =W9*45% -> 15300 | AB9: =Q9*Z9 -> 0 | AD9: =(AC9)*Z9 -> 0 | AE9: =T9 -> 0 | AG9: 0 | AH9: 0 | AI9: =SUM(AB9,AD9:AH9) -> 0 | AJ9: =ROUND(SUM(W9:X9)-AI9,0) -> 34000 | AK9: 0 | AL9: 0 | AM9: 2 lates considered for late closure. | AN9: 1750061000000170
A10: 6 | B10: R SIVARANJANI | C10: Senior Accountant | D10: 28 | E10: 0 | F10: =IF((E10/3)>=1,TRUNC(E10/3,0),0) -> 0 | G10: =E10-F10*3 -> 0 | H10: 0 | I10: =IF(H10<1,H10,H10-1) -> 0 | J10: =H10-I10 -> 0 | K10: =5+5+4.5 -> 14.5 | L10: 0.5 | M10: 1.5 | N10: 0 | O10: 0 | P10: =L10+M10+N10+O10 -> 2 | Q10: =(F10*0.5)+(I10*0.5)+M10+(N10*2) -> 1.5 | U10: =R10-(S10+T10) -> 0 | V10: 20000 | W10: =V10 -> 20000 | X10: 0 | Y10: =W10-AB10 -> 18928.571 | Z10: =V10/D10 -> 714.28571 | AA10: =W10*45% -> 9000 | AB10: =Q10*Z10 -> 1071.4286 | AD10: =(AC10)*Z10 -> 0 | AE10: =T10 -> 0 | AG10: =(AA10*12%) -> 1080 | AH10: =ROUNDUP(Y10*0.75%,0) -> 142 | AI10: =SUM(AB10,AD10:AH10) -> 2293.4286 | AJ10: =ROUND(SUM(W10:X10)-AI10,0) -> 17707 | AK10: =(AA10*13.01%) -> 1170.9 | AL10: =ROUNDUP((Y10+X10)*3.25%,0) -> 616 | AM10: 2024 & 2025 increment Rs. 10,000 will be reflected in Theni salary - MD's instruction. 5 lates considered for late closure. | AN10: 1750061000000371
R11: =SUM(R5:R10) -> 100000 | S11: =SUM(S5:S10) -> 70000 | T11: =SUM(T5:T10) -> 10000 | U11: =SUM(U5:U10) -> 20000 | V11: =SUM(V5:V10) -> 271000 | W11: =SUM(W5:W10) -> 271000 | X11: =SUM(X5:X10) -> 0 | Y11: =SUM(Y5:Y10) -> 261357.14 | ... AL11: =SUM(AL5:AL10) -> 616
A12: HR Manager | W12: Joint Director - Admin | AL12: Finance Manager
G18: =43-15 -> 28

Sheet Relieved Admin
A1: QUEEN MIRA INTERNATIONAL SCHOOL
A2: ADMIN RELIEVED - SALARY STATEMENT FEBRUARY 2026
A3: S.No | B3: Name | C3: Department | D3: Attendance | R3: Salary Advance / Loan Details | V3: Gross Salalry | W3: Payable Gross Salary | X3: Other Allownace | Y3: Salary.Actuals [Gross Salary - Leave Deduction] | Z3: Salary per day [Gross salary / no of days that month] | AA3: Basic [45% of Gross Salary] | AB3: Deductions | AJ3: Net Salary | AK3: QMIS Contribution | AM3: Remarks
D4: Total working days | E4: Lates. Actuals | F4: Lates. Leave [Exceeding lates conversions count] | G4: Final Lates after deducting exceeding Late leaves | H4: Permissions.Actuals | I4: Exceeding Permissions taken for this month | J4: Proper Permissions | K4: Proper Casual Leave already taken for this year till date | L4: Proper Casual Leave taken for this month | M4: Exceeding Casual Leave taken for this month | N4: Absent / Suspension.Actuals | O4: Gardening / Other Leave | P4: Total Leave days.Actuals | Q4: Loss of Pay Days | R4: Total Loan Amount | S4: Amount already paid | T4: Amount to be paid for this month | U4: Remaining Loan Amount | AB4: Leave / Absent / Permission Leave / Late Leave | AC4: Not Punched Days | AD4: Not Punched LOP | AE4: Salary Advance / Loan | AF4: Special Deductions [Telephone Bill + Laptop + Uniform + Trainings etc] | AG4: PF [12% of Basic Salary] | AH4: ESI [0.75% of Salary.Actuals] | AI4: Total | AK4: PF [13.01% of Basic Salary] | AL4: ESI [3.25% of Salary.Actuals]
A5: 1 | B5: BHARANI JAYAKUMAR | C5: EA to DA | D5: 9 | E5: 0 | F5: =IF((E5/3)>=1,TRUNC(E5/3,0),0) -> 0 | G5: =E5-F5*3 -> 0 | H5: 0 | I5: =IF(H5<1,H5,H5-1) -> 0 | J5: =H5-I5 -> 0 | K5: =0+0+1 -> 1 | L5: 0 | M5: 0 | N5: 0 | O5: 0 | P5: =L5+M5+N5+O5 -> 0 | Q5: =(F5*0.5)+(I5*0.5)+M5+(N5*2) -> 0 | U5: =R5-(S5+T5) -> 0 | V5: 18000 | W5: =V5/28*9 -> 5785.7143 | X5: 0 | Y5: =W5-AB5 -> 5785.7143 | Z5: =+W5/9 -> 642.85714 | AA5: =W5*45% -> 2603.5714 | AB5: =Q5*Z5 -> 0 | AD5: =(AC5)*Z5 -> 0 | AE5: =T5 -> 0 | AF5: 0 | AG5: 0 | AH5: 0 | AI5: =SUM(AB5,AD5:AH5) -> 0 | AJ5: =ROUND(SUM(W5:X5)-AI5,0) -> 5786 | AM5: Relieved on 09.02.2026. Need to pay | AN5: 1750060000002752
A6: 2 | B6: Panneer chellam. K | C6: Transport Manager | D6: 28 | E6: 0 | F6: =IF((E6/3)>=1,TRUNC(E6/3,0),0) -> 0 | G6: =E6-F6*3 -> 0 | H6: 1 | I6: =IF(H6<1,H6,H6-1) -> 0 | J6: =H6-I6 -> 1 | K6: =5+5+4 -> 14 | L6: 1 | M6: 2 | N6: 0 | O6: 0 | P6: =L6+M6+N6+O6 -> 3 | Q6: =(F6*0.5)+(I6*0.5)+M6+(N6*2) -> 2 | V6: 27000 | W6: =V6 -> 27000 | Y6: =W6-AB6 -> 25071.429 | Z6: =V6/D6 -> 964.28571 | AA6: =W6*45% -> 12150 | AB6: =Q6*Z6 -> 1928.5714 | AD6: =(AC6)*Z6 -> 0 | AE6: =T6 -> 0 | AF6: 1043 | AG6: 0 | AI6: =SUM(AB6,AD6:AH6) -> 2971.5714 | AJ6: =ROUND(SUM(W6:X6)-AI6,0) -> 24028 | AM6: Uniform 6/6 instalment deducted. Suspended on 09.01.2026. 17 lates considered for late closure. Relieved on 28.02.2026. Need to pay. | AN6: 1750061000000090
A7: 3 | B7: Gajendra prabhu | C7: Car Driver | D7: 11 | E7: 0 | F7: =IF((E7/3)>=1,TRUNC(E7/3,0),0) -> 0 | G7: =E7-F7*3 -> 0 | H7: 0 | I7: =IF(H7<2,H7,H7-2) -> 0 | J7: =H7-I7 -> 0 | K7: =0+1 -> 1 | L7: 0.5 | M7: 0 | N7: 0 | O7: 0 | P7: =L7+M7+N7+O7 -> 0.5 | Q7: =(F7*0.5)+(I7*0.5)+M7+(N7*2) -> 0 | U7: =R7-(S7+T7) -> 0 | V7: 15000 | W7: =V7/28*11 -> 5892.8571 | X7: 0 | Y7: =W7-AB7 -> 5892.8571 | Z7: =(W7+X7)/D7 -> 535.71429 | AA7: =W7*45% -> 2651.7857 | AB7: =Q7*Z7 -> 0 | AD7: =(AC7)*Z7 -> 0 | AE7: =T7 -> 0 | AF7: 2310 | AI7: =SUM(AB7,AD7:AH7) -> 2310 | AJ7: =ROUND(SUM(W7:X7)-AI7,0) -> 3583 | AM7: Reliieved on 11.02.2026 | AN7: 1750060000001605
A8: 4 | B8: Rajasekaran | C8: Car Driver | D8: 28 | E8: 0 | F8: =IF((E8/3)>=1,TRUNC(E8/3,0),0) -> 0 | G8: =E8-F8*3 -> 0 | H8: 0 | I8: =IF(H8<2,H8,H8-2) -> 0 | J8: =H8-I8 -> 0 | K8: =0+4+7 -> 11 | L8: 0 | M8: 0 | N8: 0 | O8: 0 | P8: =L8+M8+N8+O8 -> 0 | Q8: =(F8*0.5)+(I8*0.5)+M8+(N8*2) -> 0 | U8: =R8-(S8+T8) -> 0 | V8: 15000 | W8: =V8 -> 15000 | X8: 0 | Y8: =W8-AB8 -> 15000 | Z8: =(W8+X8)/D8 -> 535.71429 | AA8: =W8*45% -> 6750 | AB8: =Q8*Z8 -> 0 | AD8: =(AC8)*Z8 -> 0 | AE8: =T8 -> 0 | AI8: =SUM(AB8,AD8:AH8) -> 0 | AJ8: 0 | AM8: Whole month not reported | AN8: 1750060000000200
A9: 5 | B9: Thanu Prakash | C9: Car Driver | D9: 28 | E9: 0 | F9: =IF((E9/3)>=1,TRUNC(E9/3,0),0) -> 0 | G9: =E9-F9*3 -> 0 | H9: 0 | I9: =IF(H9<2,H9,H9-2) -> 0 | J9: =H9-I9 -> 0 | K9: =0+2+3 -> 5 | L9: 0 | M9: 0 | N9: 0 | O9: 0 | P9: =L9+M9+N9+O9 -> 0 | Q9: =(F9*0.5)+(I9*0.5)+M9+(N9*2) -> 0 | U9: =R9-(S9+T9) -> 0 | V9: 15000 | W9: =V9 -> 15000 | X9: 0 | Y9: =W9-AB9 -> 15000 | Z9: =(W9+X9)/D9 -> 535.71429 | AA9: =W9*45% -> 6750 | AB9: =Q9*Z9 -> 0 | AD9: =(AC9)*Z9 -> 0 | AE9: =T9 -> 0 | AI9: =SUM(AB9,AD9:AH9) -> 0 | AM9: Whole month not reported due to health issues. | AN9: 1750060000001357
A10: 6 | B10: Murugeshwari | C10: House keeper | D10: 28 | E10: 0 | F10: =IF((E10/3)>=1,TRUNC(E10/3,0),0) -> 0 | G10: =E10-F10*3 -> 0 | H10: 0 | I10: =IF(H10<2,H10,H10-2) -> 0 | J10: =H10-I10 -> 0 | K10: =5+5+5 -> 15 | L10: 0 | M10: 0 | N10: 0 | O10: 0 | P10: =L10+M10+N10+O10 -> 0 | Q10: =(F10*0.5)+(I10*0.5)+M10+(N10*2) -> 0 | U10: =R10-(S10+T10) -> 0 | V10: 7000 | W10: =V10 -> 7000 | X10: 0 | Y10: =W10-AB10 -> 7000 | Z10: =V10/D10 -> 250 | AA10: =W10*45% -> 3150 | AB10: =Q10*Z10 -> 0 | AD10: =(AC10)*Z10 -> 0 | AE10: =T10 -> 0 | AF10: 0 | AG10: 0 | AH10: 0 | AI10: =SUM(AB10,AD10:AH10) -> 0 | AK10: 0 | AL10: 0 | AM10: Whole month noy reported. | AN10: 1750059000000066
A11: 7 | B11: Bala Krishnan | C11: Car Driver | D11: 28 | E11: 0 | F11: =IF((E11/3)>=1,TRUNC(E11/3,0),0) -> 0 | G11: =E11-F11*3 -> 0 | H11: 0 | I11: =IF(H11<2,H11,H11-2) -> 0 | J11: =H11-I11 -> 0 | K11: =0+1.5+4.5 -> 6 | L11: 0 | M11: 0 | N11: 0 | O11: 0 | P11: =L11+M11+N11+O11 -> 0 | Q11: =(F11*0.5)+(I11*0.5)+M11+(N11*2) -> 0 | U11: =R11-(S11+T11) -> 0 | V11: 15000 | W11: =V11 -> 15000 | X11: 0 | Y11: =W11-AB11 -> 15000 | Z11: =(W11+X11)/D11 -> 535.71429 | AA11: =W11*45% -> 6750 | AB11: =Q11*Z11 -> 0 | AD11: =(AC11)*Z11 -> 0 | AE11: =T11 -> 0 | AI11: =SUM(AB11,AD11:AH11) -> 0 | AM11: Whole month not reported | AN11: 1750060000001312
A12: TOTAL | R12: =SUM(R5:R11) -> 0 | S12: =SUM(S5:S11) -> 0 | T12: =SUM(T5:T11) -> 0 | U12: =SUM(U5:U11) -> 0 | V12: =SUM(V5:V11) -> 112000 | W12: =SUM(W5:W11) -> 90678.571 | X12: =SUM(X5:X11) -> 0 | Y12: =SUM(Y5:Y11) -> 88750 | ... AL12: =SUM(AL5:AL11) -> 0
AD13: Payable salary | AJ13: =+AJ5+AJ6 -> 29814
A14: HR Manager | U14: Joint Director-Admin | AK14: Finance Manager

Sheet Drivers
A1: QUEEN MIRA INTERNATIONAL SCHOOL
A2: DRIVERS - SALARY STATEMENT FEBRUARY 2026
A3: S.No | B3: Name | C3: Department | D3: Attendance | R3: Salary Advance / Loan Details | V3: Gross Salary | W3: Payable Gross Salary | X3: Other Allownace | Y3: Salary.Actuals [Gross Salary - Leave Deduction] | Z3: Salary per day [Gross salary / no of days that month] | AA3: Basic [45% of Gross Salary] | AB3: Deductions | AJ3: Net Salary | AK3: QMIS Contribution | AM3: Remarks
D4: Total working days | E4: Lates. Actuals | F4: Lates. Leave [Exceeding lates conversions count] | G4: Final Lates after deducting exceeding Late leaves | H4: Permissions.Actuals | I4: Exceeding Permissions taken for this month | J4: Proper Permissions | K4: Proper Casual Leave already taken for this year till date | L4: Proper Casual Leave taken for this month | M4: Exceeding Casual Leave taken for this month / Memo issued | N4: Absent / Suspension.Actuals | O4: Gardening / Other Leave | P4: Total Leave days.Actuals | Q4: Loss of Pay Days | R4: Total Loan Amount | S4: Amount already paid | T4: Amount to be paid for this month | U4: Remaining Loan Amount | AB4: Leave / Absent / Permission Leave / Late Leave | AC4: Not Punched Days | AD4: Not Punched LOP | AE4: Salary Advance / Loan | AF4: Special Deductions [Telephone Bill + healthcheck up + Uniform + Trainings etc] | AG4: PF [12% of Basic Salary] | AH4: ESI [0.75% of Salary.Actuals] | AI4: Total | AK4: PF [13.01% of Basic Salary] | AL4: ESI [3.25% of Salary.Actuals]
A5: 1 | B5: KUMARAVEL MOOKKAIAH | C5: Transport Driver | D5: 28 | E5: 0 | F5: =IF((E5/3)>=1,TRUNC(E5/3,0),0) -> 0 | G5: =E5-F5*3 -> 0 | H5: 2 | I5: =IF(H5<2,H5,H5-2) -> 0 | J5: =H5-I5 -> 2 | K5: =1+5.5+1 -> 7.5 | L5: 0.5 | M5: 0 | N5: 0 | O5: 0 | P5: =L5+M5+N5+O5 -> 0.5 | Q5: =(F5*0.5)+(I5*0.5)+M5+(N5*2) -> 0 | U5: =R5-(S5+T5) -> 0 | V5: 21400 | W5: =V5 -> 21400 | X5: 0 | Y5: =(W5+X5)-AB5 -> 21400 | Z5: =(W5+X5)/D5 -> 764.28571 | AA5: =W5*45% -> 9630 | AB5: =Q5*Z5 -> 0 | AD5: =(AC5)*Z5 -> 0 | AE5: =T5 -> 0 | AG5: =ROUNDUP(AA5*12%,0) -> 1156 | AH5: 0 | AI5: =SUM(AB5,AD5:AH5) -> 1156 | AJ5: =ROUND(SUM(W5:X5)-AI5,0) -> 20244 | AK5: =ROUNDUP(AA5*13.01%,0) -> 1253 | AL5: 0 | AN5: 1750060000000508
A6: 2 | B6: DURAIMURUGAN NAGARAJAN | C6: Transport Driver | D6: 28 | E6: 0 | F6: =IF((E6/3)>=1,TRUNC(E6/3,0),0) -> 0 | G6: =E6-F6*3 -> 0 | H6: 0 | I6: =IF(H6<2,H6,H6-2) -> 0 | J6: =H6-I6 -> 0 | K6: =4+4+2.5 -> 10.5 | L6: 2.5 | M6: 0 | N6: 0 | O6: 0 | P6: =L6+M6+N6+O6 -> 2.5 | Q6: =(F6*0.5)+(I6*0.5)+M6+(N6*2) -> 0 | V6: 20800 | W6: =V6 -> 20800 | Y6: =(W6+X6)-AB6 -> 20800 | Z6: =(W6+X6)/D6 -> 742.85714 | AA6: =W6*45% -> 9360 | AB6: =Q6*Z6 -> 0 | AD6: =(AC6)*Z6 -> 0 | AE6: =T6 -> 0 | AG6: =ROUNDUP(AA6*12%,0) -> 1124 | AH6: =ROUNDUP((Y6+X6)*0.75%,0) -> 156 | AI6: =SUM(AB6,AD6:AH6) -> 1280 | AJ6: =ROUND(SUM(W6:X6)-AI6,0) -> 19520 | AK6: =ROUNDUP(AA6*13.01%,0) -> 1218 | AL6: =ROUNDUP((Y6+X6)*3.25%,0) -> 676 | AN6: 1750060000000522
A7: 3 | B7: JEYASELAN P | C7: Transport Driver | D7: 28 | E7: 0 | F7: =IF((E7/3)>=1,TRUNC(E7/3,0),0) -> 0 | G7: =E7-F7*3 -> 0 | H7: 0 | I7: =IF(H7<2,H7,H7-2) -> 0 | J7: =H7-I7 -> 0 | K7: =2.5+7.5+3 -> 13 | L7: 0 | M7: 28 | N7: 0 | O7: 0 | P7: =L7+M7+N7+O7 -> 28 | Q7: =(F7*0.5)+(I7*0.5)+M7+(N7*2) -> 28 | U7: =R7-(S7+T7) -> 0 | V7: 23200 | W7: =V7 -> 23200 | Y7: =(W7+X7)-AB7 -> 0 | Z7: =(W7+X7)/D7 -> 828.57143 | AA7: =W7*45% -> 10440 | AB7: =Q7*Z7 -> 23200 | AD7: =(AC7)*Z7 -> 0 | AE7: =T7 -> 0 | AG7: 0 | AH7: 0 | AI7: =SUM(AB7,AD7:AH7) -> 23200 | AJ7: =ROUND(SUM(W7:X7)-AI7,0) -> 0 | AK7: 0 | AL7: 0 | AM7: Whole month not reported due to health issues. | AN7: 1750060000000451
A8: 4 | B8: BALAMURUGAN AYYADURAI | C8: Transport Driver | D8: 28 | E8: 0 | F8: =IF((E8/3)>=1,TRUNC(E8/3,0),0) -> 0 | G8: =E8-F8*3 -> 0 | H8: 0 | I8: =IF(H8<2,H8,H8-2) -> 0 | J8: =H8-I8 -> 0 | K8: =1.5+3.5+4 -> 9 | L8: 0 | M8: 0 | N8: 0 | O8: 0 | P8: =L8+M8+N8+O8 -> 0 | Q8: =(F8*0.5)+(I8*0.5)+M8+(N8*2) -> 0 | U8: =R8-(S8+T8) -> 0 | V8: 20900 | W8: =V8 -> 20900 | X8: 0 | Y8: =(W8+X8)-AB8 -> 20900 | Z8: =(W8+X8)/D8 -> 746.42857 | AA8: =W8*45% -> 9405 | AB8: =Q8*Z8 -> 0 | AD8: =(AC8)*Z8 -> 0 | AE8: =T8 -> 0 | AG8: =ROUNDUP(AA8*12%,0) -> 1129 | AH8: =ROUNDUP((Y8+X8)*0.75%,0) -> 157 | AI8: =SUM(AB8,AD8:AH8) -> 1286 | AJ8: =ROUND(SUM(W8:X8)-AI8,0) -> 19614 | AK8: =ROUNDUP(AA8*13.01%,0) -> 1224 | AL8: =ROUNDUP((Y8+X8)*3.25%,0) -> 680 | AN8: 1750060000000711
A9: TOTAL | R9: =SUM(R5:R8) -> 0 | S9: =SUM(S5:S8) -> 0 | T9: =SUM(T5:T8) -> 0 | U9: =SUM(U5:U8) -> 0 | V9: =SUM(V5:V8) -> 86300 | W9: =SUM(W5:W8) -> 86300 | X9: =SUM(X5:X8) -> 0 | Y9: =SUM(Y5:Y8) -> 63100 | ... AL9: =SUM(AL5:AL8) -> 1356
A10: HR Manager | U10: Joint Director - Admin | AL10: Finance Manager

Sheet Conductors
A1: QUEEN MIRA INTERNATIONAL SCHOOL
A2: CONDUCTORS - SALARY STATEMENT FEBRUARY 2026
A3: S.No | B3: Name | C3: Department | D3: Attendance | R3: Salary Advance / Loan Details | V3: Gross Salary | W3: Payable Gross Salary | X3: Other Allownace | Y3: Salary Actuals [Gross Salary - Leave Deduction] | Z3: Salary per day [Gross salary / no of days that month] | AA3: Basic [45% of Gross Salary] | AB3: Deductions | AJ3: Net Salary | AK3: QMIS Contribution | AM3: Remarks
D4: Total working days | E4: Lates. Actuals | F4: Lates. Leave [Exceeding lates conversions count] | G4: Final Lates after deducting exceeding Late leaves | H4: Permissions.Actuals | I4: Exceeding Permissions taken for this month | J4: Proper Permissions | K4: Proper Casual Leave already taken for this year till date | L4: Proper Casual Leave taken for this month | M4: Exceeding Casual Leave taken for this month / Memo issued | N4: Absent / Suspension.Actuals | O4: Gardening / Other Leave | P4: Total Leave days.Actuals | Q4: Loss of Pay Days | R4: Total Loan Amount | S4: Amount already paid | T4: Amount to be paid for this month | U4: Remaining Loan Amount | AB4: Leave / Absent / Permission Leave / Late Leave | AC4: Not Punched Days | AD4: Not Punched LOP | AE4: Salary Advance / Loan | AF4: Special Deductions [Telephone Bill + Laptop + Uniform + Trainings etc] | AG4: PF [12% of Basic Salary] | AH4: ESI [0.75% of Salary.Actuals] | AI4: Total | AK4: PF [13.01% of Basic Salary] | AL4: ESI [3.25% of Salary.Actuals]
A5: 1 | B5: SUNDARI JEYARAM | C5: Conductor | D5: 28 | E5: 0 | F5: =IF((E5/3)>=1,TRUNC(E5/3,0),0) -> 0 | G5: =E5-F5*3 -> 0 | H5: 0 | I5: =IF(H5<2,H5,H5-2) -> 0 | J5: =H5-I5 -> 0 | K5: =1+2.5+1.5 -> 5 | L5: 1.5 | M5: 0 | N5: 0 | O5: 0 | P5: =L5+M5+N5+O5 -> 1.5 | Q5: =(F5*0.5)+(I5*0.5)+M5+(N5*2) -> 0 | R5: 0 | S5: 0 | T5: 0 | U5: =R5-(S5+T5) -> 0 | V5: 8500 | W5: =V5 -> 8500 | Y5: =(W5+X5)-AB5 -> 8500 | Z5: =(W5+X5)/D5 -> 303.57143 | AA5: =W5*45% -> 3825 | AB5: =Q5*Z5 -> 0 | AC5: 0 | AD5: =(AC5)*Z5 -> 0 | AE5: =T5 -> 0 | AG5: 0 | AH5: 0 | AI5: =SUM(AB5,AD5:AH5) -> 0 | AJ5: =ROUND(SUM(W5:X5)-AI5,0) -> 8500 | AK5: 0 | AL5: 0 | AN5: 1750059000000054
A6: 2 | B6: S CHITRA | C6: Conductor | D6: 28 | E6: 0 | F6: =IF((E6/3)>=1,TRUNC(E6/3,0),0) -> 0 | G6: =E6-F6*3 -> 0 | H6: 2 | I6: =IF(H6<2,H6,H6-2) -> 0 | J6: =H6-I6 -> 2 | K6: =0+0.5+1.5 -> 2 | L6: 0 | M6: 0 | N6: 0 | O6: 0 | P6: =L6+M6+N6+O6 -> 0 | Q6: =(F6*0.5)+(I6*0.5)+M6+(N6*2) -> 0 | R6: 0 | S6: 0 | T6: 0 | U6: =R6-(S6+T6) -> 0 | V6: 11700 | W6: =V6 -> 11700 | Y6: =(W6+X6)-AB6 -> 11700 | Z6: =(W6+X6)/D6 -> 417.85714 | AA6: =W6*45% -> 5265 | AB6: =Q6*Z6 -> 0 | AD6: =(AC6)*Z6 -> 0 | AE6: =T6 -> 0 | AG6: =ROUNDUP(AA6*12%,0) -> 632 | AH6: =ROUNDUP((Y6+X6)*0.75%,0) -> 88 | AI6: =SUM(AB6,AD6:AH6) -> 720 | AJ6: =ROUND(SUM(W6:X6)-AI6,0) -> 10980 | AK6: =ROUNDUP(AA6*13.01%,0) -> 685 | AL6: =ROUNDUP((Y6+X6)*3.25%,0) -> 381 | AN6: 1750059000000281
A7: 3 | B7: GNANAMANI SANKARALINGAM | C7: Conductor | D7: 28 | E7: 0 | F7: =IF((E7/3)>=1,TRUNC(E7/3,0),0) -> 0 | G7: =E7-F7*3 -> 0 | H7: 0 | I7: =IF(H7<2,H7,H7-2) -> 0 | J7: =H7-I7 -> 0 | K7: =2+1.5+1 -> 4.5 | L7: 0.5 | M7: 0 | N7: 0 | O7: 0 | P7: =L7+M7+N7+O7 -> 0.5 | Q7: =(F7*0.5)+(I7*0.5)+M7+(N7*2) -> 0 | R7: 0 | S7: 0 | T7: 0 | U7: 0 | V7: 9900 | W7: =V7 -> 9900 | Y7: =(W7+X7)-AB7 -> 9900 | Z7: =(W7+X7)/D7 -> 353.57143 | AA7: =W7*45% -> 4455 | AB7: =Q7*Z7 -> 0 | AD7: =(AC7)*Z7 -> 0 | AE7: =T7 -> 0 | AG7: =ROUNDUP(AA7*12%,0) -> 535 | AH7: =ROUNDUP((Y7+X7)*0.75%,0) -> 75 | AI7: =SUM(AB7,AD7:AH7) -> 610 | AJ7: =ROUND(SUM(W7:X7)-AI7,0) -> 9290 | AK7: =ROUNDUP(AA7*13.01%,0) -> 580 | AL7: =ROUNDUP((Y7+X7)*3.25%,0) -> 322 | AN7: 1750059000000080
A8: 4 | B8: SANTHI S | C8: Conductor | D8: 28 | E8: 0 | F8: =IF((E8/3)>=1,TRUNC(E8/3,0),0) -> 0 | G8: =E8-F8*3 -> 0 | H8: 0 | I8: =IF(H8<2,H8,H8-2) -> 0 | J8: =H8-I8 -> 0 | K8: =5+5+5 -> 15 | L8: 0 | M8: 21 | N8: 0 | O8: 0 | P8: =L8+M8+N8+O8 -> 21 | Q8: =(F8*0.5)+(I8*0.5)+M8+(N8*2) -> 21 | V8: 12100 | W8: =V8 -> 12100 | Y8: =(W8+X8)-AB8 -> 3025 | Z8: =(W8+X8)/D8 -> 432.14286 | AA8: =W8*45% -> 5445 | AB8: =Q8*Z8 -> 9075 | AD8: =(AC8)*Z8 -> 0 | AE8: =T8 -> 0 | AG8: =ROUNDUP(AA8*12%,0) -> 654 | AH8: =ROUNDUP((Y8+X8)*0.75%,0) -> 23 | AI8: =SUM(AB8,AD8:AH8) -> 9752 | AJ8: =ROUND(SUM(W8:X8)-AI8,0) -> 2348 | AK8: =ROUNDUP(AA8*13.01%,0) -> 709 | AL8: =ROUNDUP((Y8+X8)*3.25%,0) -> 99 | AM8: Long leave due to husband demise. | AN8: 1750060000001014
A9: 5 | B9: KALEESWARI RAJA | C9: Conductor | D9: 28 | E9: 0 | F9: =IF((E9/3)>=1,TRUNC(E9/3,0),0) -> 0 | G9: =E9-F9*3 -> 0 | H9: 0 | I9: =IF(H9<2,H9,H9-2) -> 0 | J9: =H9-I9 -> 0 | K9: =3.5+6+2.5 -> 12 | L9: 2.5 | M9: 0 | N9: 0 | O9: 0 | P9: =L9+M9+N9+O9 -> 2.5 | Q9: =(F9*0.5)+(I9*0.5)+M9+(N9*2) -> 0 | V9: 9100 | W9: =V9 -> 9100 | Y9: =(W9+X9)-AB9 -> 9100 | Z9: =(W9+X9)/D9 -> 325 | AA9: =W9*45% -> 4095 | AB9: =Q9*Z9 -> 0 | AD9: =(AC9)*Z9 -> 0 | AE9: =T9 -> 0 | AG9: 0 | AH9: 0 | AI9: =SUM(AB9,AD9:AH9) -> 0 | AJ9: =ROUND(SUM(W9:X9)-AI9,0) -> 9100 | AK9: 0 | AL9: 0 | AN9: 1750059000000302
A10: TOTAL | R10: =SUM(R5:R9) -> 0 | S10: =SUM(S5:S9) -> 0 | T10: =SUM(T5:T9) -> 0 | U10: =SUM(U5:U9) -> 0 | V10: =SUM(V5:V9) -> 51300 | W10: =SUM(W5:W9) -> 51300 | X10: =SUM(X5:X9) -> 0 | Y10: =SUM(Y5:Y9) -> 42225 | ... AM10: =SUM(AM5:AM9) -> 0 | AO10: =SUM(AO5:AO9) -> 0
A11: HR Manager | U11: Joint Director - Admin | AL11: Finance Manager

Sheet Securities
A1: QUEEN MIRA INTERNATIONAL SCHOOL
A2: SECURITIES - SALARY STATEMENT FEBRUARY 2026
A3: S.No | B3: Name | C3: Department | D3: Attendance | R3: Salary Advance / Loan Details | V3: Gross Salary | W3: Payable Gross Salary | X3: Other Allownace | Y3: Salary.Actuals [Gross Salary - Leave Deduction] | Z3: Salary per day [Gross salary / no of days that month] | AA3: Basic [45% of Gross Salary] | AB3: Deductions | AJ3: Net Salary | AK3: QMIS Contribution | AM3: Remarks
D4: Total working days | E4: Lates. Actuals | F4: Lates. Leave [Exceeding lates conversions count] | G4: Final Lates after deducting exceeding Late leaves | H4: Permissions.Actuals | I4: Exceeding Permissions taken for this month | J4: Proper Permissions | K4: Proper Casual Leave already taken for this year till date | L4: Proper Casual Leave taken for this month | M4: Exceeding Casual Leave taken for this month / Memo issued | N4: Absent / Suspension.Actuals | O4: Gardening / Other Leave | P4: Total Leave days.Actuals | Q4: Loss of Pay Days | R4: Total Loan Amount | S4: Amount already paid | T4: Amount to be paid for this month | U4: Remaining Loan Amount | AB4: Leave / Absent / Permission Leave / Late Leave | AC4: Not Punched Days | AD4: Not Punched LOP | AE4: Salary Advance / Loan | AF4: Special Deductions [Telephone Bill + Laptop + Uniform + Trainings etc] | AG4: PF [12% of Basic Salary] | AH4: ESI [0.75% of Salary.Actuals] | AI4: Total | AK4: PF [13.01% of Basic Salary] | AL4: ESI [3.25% of Salary.Actuals]
A5: 1 | B5: VAIRAMANI S/O BOSE | C5: Child Safety Officer | D5: 28 | E5: 0 | F5: =IF((E5/3)>=1,TRUNC(E5/3,0),0) -> 0 | G5: =E5-F5*3 -> 0 | H5: 2 | I5: =IF(H5<2,H5,H5-2) -> 0 | J5: =H5-I5 -> 2 | K5: =3+4.5+0 -> 7.5 | L5: 0.5 | M5: 0 | N5: 0 | O5: 0 | P5: =L5+M5+N5+O5 -> 0.5 | Q5: =(F5*0.5)+(I5*0.5)+L5+(N5*2)+M5 -> 0.5 | R5: =150000+200000 -> 350000 | S5: =87000+10000+10000+10000+10000+10000+10000+10000+10000+10000+10000+10000+10000+10000 -> 217000 | T5: 10000 | U5: =R5-(S5+T5) -> 123000 | V5: 22700 | W5: =V5 -> 22700 | X5: 0 | Y5: =W5-AB5 -> 22294.643 | Z5: =W5/D5 -> 810.71429 | AA5: =W5*45% -> 10215 | AB5: =Q5*Z5 -> 405.35714 | AD5: =(AC5)*Z5 -> 0 | AE5: =T5 -> 10000 | AG5: 0 | AH5: 0 | AI5: =SUM(AB5,AD5:AH5) -> 10405.357 | AJ5: =ROUND(SUM(W5:X5)-AI5,0) -> 12295 | AK5: 0 | AL5: 0 | AM5: Salary Adv Pg.No: 59 & 7. | AN5: 1750059000000196
A6: 2 | B6: MOHAMED ALI JINNA A | C6: Security Officer | D6: 28 | E6: 0 | F6: =IF((E6/3)>=1,TRUNC(E6/3,0),0) -> 0 | G6: =E6-F6*3 -> 0 | H6: 0 | I6: =IF(H6<2,H6,H6-2) -> 0 | J6: =H6-I6 -> 0 | K6: =11+16.5+1.5 -> 29 | L6: 0 | M6: 0 | N6: 0 | O6: 0 | P6: =L6+M6+N6+O6 -> 0 | Q6: =(F6*0.5)+(I6*0.5)+L6+(N6*2)+M6 -> 0 | U6: =R6-(S6+T6) -> 0 | V6: 17500 | W6: =V6 -> 17500 | X6: 0 | Y6: =W6-AB6 -> 17500 | Z6: =W6/D6 -> 625 | AA6: =W6*45% -> 7875 | AB6: =Q6*Z6 -> 0 | AD6: =(AC6)*Z6 -> 0 | AE6: =T6 -> 0 | AG6: 0 | AH6: 0 | AI6: =SUM(AB6,AD6:AH6) -> 0 | AJ6: =ROUND(SUM(W6:X6)-AI6,0) -> 17500 | AK6: 0 | AL6: 0 | AN6: 1750060000000380
A7: 3 | B7: AYYANAR P | C7: Security Officer | D7: 28 | E7: 0 | F7: =IF((E7/3)>=1,TRUNC(E7/3,0),0) -> 0 | G7: =E7-F7*3 -> 0 | H7: 0 | I7: =IF(H7<2,H7,H7-2) -> 0 | J7: =H7-I7 -> 0 | K7: =4+0+4 -> 8 | L7: 0 | M7: 0 | N7: 0 | O7: 0 | P7: =L7+M7+N7+O7 -> 0 | Q7: =(F7*0.5)+(I7*0.5)+L7+(N7*2)+M7 -> 0 | U7: =R7-(S7+T7) -> 0 | V7: 15800 | W7: =V7 -> 15800 | X7: 0 | Y7: =W7-AB7 -> 15800 | Z7: =W7/D7 -> 564.28571 | AA7: =W7*45% -> 7110 | AB7: =Q7*Z7 -> 0 | AD7: =(AC7)*Z7 -> 0 | AE7: =T7 -> 0 | AG7: 0 | AH7: 0 | AI7: =SUM(AB7,AD7:AH7) -> 0 | AJ7: =ROUND(SUM(W7:X7)-AI7,0) -> 15800 | AK7: 0 | AL7: 0 | AN7: 1750060000001170
A8: TOTAL | R8: =SUM(R5:R7) -> 350000 | S8: =SUM(S5:S7) -> 217000 | T8: =SUM(T5:T7) -> 10000 | U8: =SUM(U5:U7) -> 123000 | V8: =SUM(V5:V7) -> 56000 | W8: =SUM(W5:W7) -> 56000 | X8: =SUM(X5:X7) -> 0 | Y8: =SUM(Y5:Y7) -> 55594.643 | ... AM8: =SUM(AM5:AM7) -> 0
A9: HR Manager | U9: Joint Director - Admin | AL9: Finance Manager

Sheet House Keeping
A1: QUEEN MIRA INTERNATIONAL SCHOOL
A2: HOUSE KEEPING - SALARY STATEMENT FEBRUARY 2026
A3: S.No | B3: Name | C3: Department | D3: Attendance | R3: Salary Advance / Loan Details | V3: Gross Salary | W3: Payable Gross Salary | X3: Other Allownace | Y3: Salary.Actuals [Gross Salary - Leave Deduction] | Z3: Salary per day [Gross salary / no of days that month] | AA3: Basic [45% of Gross Salary] | AB3: Deductions | AJ3: Net Salary | AK3: QMIS Contribution | AM3: Remarks
D4: Total working days | E4: Lates. Actuals | F4: Lates. Leave [Exceeding lates conversions count] | G4: Final Lates after deducting exceeding Late leaves | H4: Permissions.Actuals | I4: Exceeding Permissions taken for this month | J4: Proper Permissions | K4: Proper Casual Leave already taken for this year till date | L4: Proper Casual Leave taken for this month | M4: Exceeding Casual Leave taken for this month / Memo issued | N4: Absent / Suspension.Actuals | O4: Gardening / Other Leave | P4: Total Leave days.Actuals | Q4: Loss of Pay Days | R4: Total Loan Amount | S4: Amount already paid | T4: Amount to be paid for this month | U4: Remaining Loan Amount | AB4: Leave / Absent / Permission Leave / Late Leave | AC4: Not Punched Days | AD4: Not Punched LOP | AE4: Salary Advance / Loan | AF4: Special Deductions [Telephone Bill + Laptop + Uniform + Trainings etc] | AG4: PF [12% of Basic Salary] | AH4: ESI [0.75% of Salary.Actuals] | AI4: Total | AK4: PF [13.01% of Basic Salary] | AL4: ESI [3.25% of Salary.Actuals]
A5: 1 | B5: AMARAVALLI W/O RAJANGAM | C5: Janitor | D5: 28 | E5: 2 | F5: =IF((E5/3)>=1,TRUNC(E5/3,0),0) -> 0 | G5: =E5-F5*3 -> 2 | H5: 0 | I5: =IF(H5<1,H5,H5-1) -> 0 | J5: =H5-I5 -> 0 | K5: =5+4+2 -> 11 | L5: 1 | M5: 0 | N5: 0 | O5: 0 | P5: =L5+M5+N5+O5 -> 1 | Q5: =(F5*0.5)+(I5*0.5)+M5+(N5*2) -> 0 | U5: =R5-(S5+T5) -> 0 | V5: 12400 | W5: =V5 -> 12400 | Y5: =(W5+X5)-AB5 -> 12400 | Z5: =V5/D5 -> 442.85714 | AA5: =W5*45% -> 5580 | AB5: =Q5*Z5 -> 0 | AD5: =(AC5)*Z5 -> 0 | AE5: =T5 -> 0 | AG5: =ROUNDUP(AA5*12%,0) -> 670 | AH5: =ROUNDUP((Y5+X5)*0.75%,0) -> 93 | AI5: =SUM(AB5,AD5:AH5) -> 763 | AJ5: =ROUND(SUM(W5:X5)-AI5,0) -> 11637 | AK5: =ROUNDUP(AA5*13.01%,0) -> 726 | AL5: =ROUNDUP((Y5+X5)*3.25%,0) -> 403 | AN5: 1750060000000886
A6: 2 | B6: PARVATHI W/O MUTHAIAH | C6: Janitor | D6: 28 | E6: 1 | F6: =IF((E6/3)>=1,TRUNC(E6/3,0),0) -> 0 | G6: =E6-F6*3 -> 1 | H6: 0 | I6: =IF(H6<1,H6,H6-1) -> 0 | J6: =H6-I6 -> 0 | K6: =5+4+1 -> 10 | L6: 2 | M6: 0 | N6: 0 | O6: 0 | P6: =L6+M6+N6+O6 -> 2 | Q6: =(F6*0.5)+(I6*0.5)+M6+(N6*2) -> 0 | R6: 20000 | S6: =2000+2000+2000 -> 6000 | T6: 2000 | U6: =R6-(S6+T6) -> 12000 | V6: 11700 | W6: =V6 -> 11700 | Y6: =(W6+X6)-AB6 -> 11700 | Z6: =V6/D6 -> 417.85714 | AA6: =W6*45% -> 5265 | AB6: =Q6*Z6 -> 0 | AD6: =(AC6)*Z6 -> 0 | AE6: =T6 -> 2000 | AG6: =ROUNDUP(AA6*12%,0) -> 632 | AH6: =ROUNDUP((Y6+X6)*0.75%,0) -> 88 | AI6: =SUM(AB6,AD6:AH6) -> 2720 | AJ6: =ROUND(SUM(W6:X6)-AI6,0) -> 8980 | AK6: =ROUNDUP(AA6*13.01%,0) -> 685 | AL6: =ROUNDUP((Y6+X6)*3.25%,0) -> 381 | AM6: Salary Adv Note: 4Pg.No: 30 | AN6: 1750059000000231
A7: 3 | B7: UMARANI B | C7: Janitor | D7: 28 | E7: 4 | F7: =IF((E7/3)>=1,TRUNC(E7/3,0),0) -> 1 | G7: =E7-F7*3 -> 1 | H7: 0 | I7: =IF(H7<2,H7,H7-2) -> 0 | J7: =H7-I7 -> 0 | K7: =5+5+3.5 -> 13.5 | L7: 1 | M7: 1 | N7: 0 | O7: 0 | P7: =L7+M7+N7+O7 -> 2 | Q7: =(F7*0.5)+(I7*0.5)+M7+(N7*2) -> 1.5 | R7: 10000 | S7: =1000+1000+1000+1000+1000+1000 -> 6000 | T7: 1000 | U7: =R7-(S7+T7) -> 3000 | V7: 8700 | W7: =V7 -> 8700 | Y7: =(W7+X7)-AB7 -> 8233.9286 | Z7: =V7/D7 -> 310.71429 | AA7: =W7*45% -> 3915 | AB7: =Q7*Z7 -> 466.07143 | AD7: =(AC7)*Z7 -> 0 | AE7: =T7 -> 1000 | AG7: =ROUNDUP(AA7*12%,0) -> 470 | AH7: =ROUNDUP((Y7+X7)*0.75%,0) -> 62 | AI7: =SUM(AB7,AD7:AH7) -> 1998.0714 | AJ7: =ROUND(SUM(W7:X7)-AI7,0) -> 6702 | AK7: =ROUNDUP(AA7*13.01%,0) -> 510 | AL7: =ROUNDUP((Y7+X7)*3.25%,0) -> 268 | AM7: Salary Adv Note: 4Pg.No: 25. 1 memo issued. | AN7: 1750060000000330
A8: 4 | B8: PANJU T | C8: MD Maid | D8: 28 | E8: 0 | F8: =IF((E8/3)>=1,TRUNC(E8/3,0),0) -> 0 | G8: =E8-F8*3 -> 0 | H8: 0 | I8: =IF(H8<2,H8,H8-2) -> 0 | J8: =H8-I8 -> 0 | K8: =6+4+3 -> 13 | L8: 3 | M8: 11 | N8: 0 | O8: 0 | P8: =L8+M8+N8+O8 -> 14 | Q8: =(F8*0.5)+(I8*0.5)+M8+(N8*2) -> 11 | R8: 0 | S8: 0 | T8: 0 | U8: =R8-(S8+T8) -> 0 | V8: 16300 | W8: =V8 -> 16300 | X8: 0 | Y8: =(W8+X8)-AB8 -> 9896.4286 | Z8: =V8/D8 -> 582.14286 | AA8: =W8*45% -> 7335 | AB8: =Q8*Z8 -> 6403.5714 | AD8: =(AC8)*Z8 -> 0 | AE8: =T8 -> 0 | AG8: 0 | AH8: =ROUNDUP((Y8+X8)*0.75%,0) -> 75 | AI8: =SUM(AB8,AD8:AH8) -> 6478.5714 | AJ8: =ROUND(SUM(W8:X8)-AI8,0) -> 9821 | AK8: 0 | AL8: =ROUNDUP((Y8+X8)*3.25%,0) -> 322 | AM8: As per MD's instruction per month she is eligible for 3 CL. | AN8: 1750060000000602
A9: TOTAL | R9: =SUM(R5:R8) -> 30000 | S9: =SUM(S5:S8) -> 12000 | T9: =SUM(T5:T8) -> 3000 | U9: =SUM(U5:U8) -> 15000 | V9: =SUM(V5:V8) -> 49100 | W9: =SUM(W5:W8) -> 49100 | X9: =SUM(X5:X8) -> 0 | Y9: =SUM(Y5:Y8) -> 42230.357 | ... AM9: =SUM(AM5:AM8) -> 0
A10: HR Manager | W10: Joint Director - Admin | AL10: Finance Manager

Sheet Hostel
A1: QUEEN MIRA INTERNATIONAL SCHOOL
A2: HOSTEL - SALARY STATEMENT FEBRUARY 2026
A3: S.No | B3: Name | C3: Department | D3: Attendance | R3: Salary Advance / Loan Details | V3: Gross Salary | W3: Payable Gross Salary | X3: Other Allownace | Y3: Salary.Actuals [Gross Salary - Leave Deduction] | Z3: Salary per day [Gross salary / no of days that month] | AA3: Basic [45% of Gross Salary] | AB3: Deductions | AJ3: Net Salary | AK3: QMIS Contribution | AM3: Remarks
D4: Total working days | E4: Lates. Actuals | F4: Lates. Leave [Exceeding lates conversions count] | G4: Final Lates after deducting exceeding Late leaves | H4: Permissions.Actuals | I4: Exceeding Permissions taken for this month | J4: Proper Permissions | K4: Proper Casual Leave already taken for this year till date | L4: Proper Casual Leave taken for this month | M4: Exceeding Casual Leave taken for this month / Memo issued | N4: Absent / Suspension.Actuals | O4: Gardening / Other Leave | P4: Total Leave days.Actuals | Q4: Loss of Pay Days | R4: Total Loan Amount | S4: Amount already paid | T4: Amount to be paid for this month | U4: Remaining Loan Amount | AB4: Leave / Absent / Permission Leave / Late Leave | AC4: Not Punched Days | AD4: Not Punched LOP | AE4: Salary Advance / Loan | AF4: Special Deductions [Telephone Bill + Laptop + Uniform + Trainings etc] | AG4: PF [12% of Basic Salary] | AH4: ESI [0.75% of Salary.Actuals] | AI4: Total | AK4: PF [13.01% of Basic Salary] | AL4: ESI [3.25% of Salary.Actuals]
A5: 1 | B5: Pangajam | C5: Chef | D5: 28 | E5: 0 | F5: =IF((E5/3)>=1,TRUNC(E5/3,0),0) -> 0 | G5: =E5-F5*3 -> 0 | H5: 0 | I5: =IF(H5<2,H5,H5-2) -> 0 | J5: =H5-I5 -> 0 | K5: =0+5 -> 5 | L5: 0 | M5: 0 | N5: 0 | O5: 0 | P5: =L5+M5+N5+O5 -> 0 | Q5: =(F5*0.5)+(I5*0.5)+L5+(N5*2)+M5 -> 0 | T5: 0 | U5: =R5-(S5+T5) -> 0 | V5: 26000 | W5: =V5 -> 26000 | X5: 0 | Y5: =V5-AB5 -> 26000 | Z5: =(V5+X5)/28 -> 928.57143 | AA5: =V5*45% -> 11700 | AB5: =Q5*Z5 -> 0 | AD5: =(AC5)*Z5 -> 0 | AE5: =T5 -> 0 | AG5: 0 | AH5: 0 | AI5: =SUM(AB5,AD5:AH5) -> 0 | AJ5: =ROUND(SUM(W5:X5)-AI5,0) -> 26000 | AK5: 0 | AL5: 0 | AN5: 1750060000001345
A6: 2 | B6: Meena | C6: Chef | D6: 28 | E6: 0 | F6: =IF((E6/3)>=1,TRUNC(E6/3,0),0) -> 0 | G6: =E6-F6*3 -> 0 | H6: 0 | I6: =IF(H6<2,H6,H6-2) -> 0 | J6: =H6-I6 -> 0 | K6: =0+0 -> 0 | L6: 0 | M6: 1 | N6: 0 | O6: 0 | P6: =L6+M6+N6+O6 -> 1 | Q6: =(F6*0.5)+(I6*0.5)+L6+(N6*2)+M6 -> 1 | T6: 0 | U6: =R6-(S6+T6) -> 0 | V6: 7000 | W6: =V6 -> 7000 | X6: 0 | Y6: =V6-AB6 -> 6750 | Z6: =(V6+X6)/28 -> 250 | AA6: =V6*45% -> 3150 | AB6: =Q6*Z6 -> 250 | AD6: =(AC6)*Z6 -> 0 | AE6: =T6 -> 0 | AG6: 0 | AH6: 0 | AI6: =SUM(AB6,AD6:AH6) -> 250 | AJ6: =ROUND(SUM(W6:X6)-AI6,0) -> 6750 | AK6: 0 | AL6: 0 | AM6: Leave on 04.02.2026 | AN6: 1750060000002123
A7: 3 | B7: AARTHY SELVAM | C7: Hostel Warden | D7: 28 | E7: 0 | F7: =IF((E7/3)>=1,TRUNC(E7/3,0),0) -> 0 | G7: =E7-F7*3 -> 0 | H7: 0 | I7: =IF(H7<1,H7,H7-1) -> 0 | J7: =H7-I7 -> 0 | K7: =1.5+4.5+2.5 -> 8.5 | L7: 0.5 | M7: 0 | N7: 0 | O7: 0 | P7: =L7+M7+N7+O7 -> 0.5 | Q7: =(F7*0.5)+(I7*0.5)+M7+(N7*2) -> 0 | U7: =R7-(S7+T7) -> 0 | V7: 5000 | W7: =V7 -> 5000 | X7: 0 | Y7: =V7-AB7 -> 5000 | Z7: =(V7+X7)/28 -> 178.57143 | AA7: =V7*45% -> 2250 | AB7: =Q7*Z7 -> 0 | AD7: =(AC7)*Z7 -> 0 | AE7: =T7 -> 0 | AF7: 0 | AG7: 0 | AH7: 0 | AI7: =SUM(AB7,AD7:AH7) -> 0 | AJ7: =ROUND(SUM(W7:X7)-AI7,0) -> 5000 | AK7: 0 | AL7: 0 | AN7: 1750060000001274
A8: TOTAL | R8: =SUM(R5:R7) -> 0 | S8: =SUM(S5:S7) -> 0 | T8: =SUM(T5:T7) -> 0 | U8: =SUM(U5:U7) -> 0 | V8: =SUM(V5:V7) -> 38000 | W8: =SUM(W5:W7) -> 38000 | X8: =SUM(X5:X7) -> 0 | Y8: =SUM(Y5:Y7) -> 37750 | ... AL8: =SUM(AL5:AL7) -> 0
A9: HR Manager | V9: Director Academics | AL9: Finance Manager
R15: =(G15*0.5)+(J15*0.5)+N15+(O15*2) -> 0

Sheet ECA - Regular
A1: QUEEN MIRA INTERNATIONAL SCHOOL
A2: ECA REGULAR - SALARY STATEMENT FEBRUARY 2026
A3: ECA Staff - Regular Salary
A4: S.No | B4: Name | C4: Department | D4: Gross Salary | E4: Total No.of Classes | F4: No.of days Leave | G4: Advance Total | H4: Already Paid | I4: Pending Deduction | J4: Current Month deduction | K4: Leave Deduction Amt | L4: Other Deductions | M4: Net Salary | N4: Remarks
A5: 1 | B5: R BALACHANDER | C5: Western Dance | D5: 18000 | E5: 0 | F5: 2 | G5: 0 | I5: 0 | J5: 0 | K5: =D5/8*F5 -> 4500 | L5: 0 | M5: =ROUND(D5-J5-K5-L5,0) -> 13500 | O5: 1750060000000106
A6: 2 | B6: ARAVINDHU PASHWAN VELAYUTHAM | C6: Guitar | D6: 11600 | E6: 0 | F6: 0 | G6: 0 | I6: 0 | J6: 0 | K6: =D6/8*F6 -> 0 | L6: 0 | M6: =ROUND(D6-J6-K6-L6,0) -> 11600 | O6: 1750061000000241
A7: 3 | B7: J RAJA / Chandra | C7: Silambam | D7: 12200 | E7: 0 | F7: 0 | G7: 0 | I7: 0 | J7: 0 | K7: =D7/8*F7 -> 0 | L7: 0 | M7: =ROUND(D7-J7-K7-L7,0) -> 12200 | O7: 1750060000001298
A8: 4 | B8: J RAJA / Amutheswaran | C8: Karate | D8: 11600 | E8: 0 | F8: 0 | G8: 0 | I8: 0 | J8: 0 | K8: =D8/8*F8 -> 0 | L8: 0 | M8: =ROUND(D8-J8-K8-L8,0) -> 11600 | O8: 1750060000001298
A9: Total | D9: =SUM(D5:D8) -> 53400 | E9: =SUM(E5:E8) -> 0 | F9: =SUM(F5:F8) -> 2 | G9: =SUM(G5:G8) -> 0 | H9: =SUM(H5:H8) -> 0 | I9: =SUM(I5:I8) -> 0 | J9: =SUM(J5:J8) -> 0 | K9: =SUM(K5:K8) -> 4500 | ... M9: =SUM(M5:M8) -> 48900
A10: HR Manager Director Academics Finance Manager

Sheet  Part Time - Academics
A1: QUEEN MIRA INTERNATIONAL SCHOOL
A2: ACADEMICS PART TIME - SALARY STATEMENT FEBRUARY 2026
A3: S.No | B3: Name | C3: Department | D3: Gross Salary | E3: Other Allowance | F3: Classes Taken | G3: Per Day Salary | H3: Advance Total | I3: Advance Deduction | J3: No. Of Leaves | K3: To be Deducted | L3: Other Deduction | M3: Leave Deductions | N3: Total Deductions | O3: Net Salary | P3: Remarks
A4: 1 | B4: I PRADEEP CHRISTOPHER | C4: French | D4: 29000 | E4: 0 | F4: 16 | G4: =D4/28 -> 1035.7143 | H4: 0 | I4: 0 | J4: 0 | K4: 0 | L4: 0 | M4: =G4*J4 -> 0 | N4: =I4+M4+L4 -> 0 | O4: =ROUND(D4-N4,0)+E4 -> 29000 | Q4: 1750061000000362
A5: 2 | B5: DHARANI W/O SRINIVAS | C5: School Counsellor | D5: 42000 | F5: 12 | G5: =D5/28 -> 1500 | H5: 0 | I5: 0 | J5: 0 | K5: 0 | M5: =G5*J5 -> 0 | N5: =I5+M5+L5 -> 0 | O5: =ROUND(D5-N5,0)+E5 -> 42000 | Q5: 1750061000000220
A6: 3 | B6: ARCHANAA W/O KARTHIKEYAN | C6: IT | D6: 19800 | F6: 13 | G6: =D6/28 -> 707.14286 | H6: 0 | I6: 0 | J6: 0 | K6: =H6-I6 -> 0 | M6: =G6*J6 -> 0 | N6: =I6+M6+L6 -> 0 | O6: =ROUND(D6-N6,0)+E6 -> 19800 | P6: 0.5 leave considered as he/she worked on 20..01.2026 & 24..01.2026 | Q6: 1750060000000768
A7: 4 | B7: Jeyabal J | C7: Creative space | D7: =450*F7 -> 13950 | F7: 31 | G7: =D7/28 -> 498.21429 | H7: 0 | I7: 0 | J7: 0 | K7: =H7-I7 -> 0 | M7: =G7*J7 -> 0 | N7: =I7+M7+L7 -> 0 | O7: =ROUND(D7-N7,0)+E7 -> 13950 | P7: (Actual classes to be planned 8 days * 8 periods = 64 periods for each) Per period Rs 450 | Q7: 1105155000093166
A8: 5 | B8: Niveth Oliviya | C8: Creative space | D8: =450*F8 -> 28800 | F8: 64 | G8: =D8/28 -> 1028.5714 | H8: 0 | I8: 0 | J8: 0 | K8: =H8-I8 -> 0 | M8: =G8*J8 -> 0 | N8: =I8+M8+L8 -> 0 | O8: =ROUND(D8-N8,0)+E8 -> 28800 | Q8: 1750060000001203
A9: Total | D9: =SUM(D4:D8) -> 133550 | E9: =SUM(E4:E8) -> 0 | F9: =SUM(F4:F8) -> 136 | G9: =SUM(G4:G8) -> 4769.6429 | H9: =SUM(H4:H8) -> 0 | I9: =SUM(I4:I8) -> 0 | J9: =SUM(J4:J8) -> 0 | K9: =SUM(K4:K8) -> 0 | ... O9: =SUM(O4:O8) -> 133550
A10: HR Manager | H10: Director Academics | O10: Finance Manager

Sheet Aca +ECA = Spl
A1: QUEEN MIRA INTERNATIONAL SCHOOL
A2: ACADEMICS AND ECA - SPECIAL - SALARY STATEMENT FEBRUARY 2026
A3: S.No | B3: Name | C3: Department | D3: Gross Salary | E3: Classes taken / Days reported | F3: Per Day Salary | G3: No. of Leaves | H3: Special Deductions | I3: Leave Deductions | J3: Net Salary | K3: Remarks
A4: 1 | B4: ARUNKANTH MURUGAN | C4: Table Tennis | D4: 18550 | E4: 20 | F4: =D4/28 -> 662.5 | G4: 0 | I4: =F4*G4 -> 0 | J4: =ROUND(D4-I4-H4,0) -> 18550 | L4: 1750061000000348
A5: 2 | B5: Chandrashekaran | C5: Chemistry | D5: =E5*1500 -> 72000 | E5: 48 | F5: =D5/28 -> 2571.4286 | G5: 0 | H5: 0 | I5: =F5*G5 -> 0 | J5: =ROUND(D5-I5-H5,0) -> 72000 | K5: 1500 Per hour. | L5: Cash
A6: 3 | B6: Sudha | C6: Biology | D6: =E6*1200 -> 0 | E6: 0 | F6: =D6/28 -> 0 | G6: 0 | I6: =F6*G6 -> 0 | J6: =ROUND(D6-I6-H6,0) -> 0 | K6: 1200 Per hour. | L6: 1750061000000383
A7: 4 | B7: DANIEL MERWIN SELVARAJ | C7: Skatting Coach | D7: 24000 | E7: 19 | F7: =D7/28 -> 857.14286 | G7: 0 | I7: =F7*G7 -> 0 | J7: =ROUND(D7-I7-H7,0) -> 24000 | L7: 1750061000000289
A8: 5 | B8: Thirubuvan | C8: Physics | D8: =E8*1050 -> 37275 | E8: 35.5 | F8: =D8/28 -> 1331.25 | G8: 0 | H8: 0 | I8: =F8*G8 -> 0 | J8: =ROUND(D8-I8-H8,0) -> 37275 | K8: 1050 Per hour. | L8: 1750061000000419
A9: Total | D9: =SUM(D4:D8) -> 151825 | E9: =SUM(E4:E8) -> 122.5 | F9: =SUM(F4:F8) -> 5422.3214 | G9: =SUM(G4:G8) -> 0 | H9: =SUM(H4:H8) -> 0 | I9: =SUM(I4:I8) -> 0 | J9: =SUM(J4:J8) -> 151825
A10: HR Manager | E10: Director Academics | K10: Finance Manager

Sheet Theni - Upparpatti
A1: QUEEN MIRA INTERNATIONAL SCHOOL
A2: THENI UPPARPATTI - SALARY STATEMENT FEBRUARY 2026
A3: S.No | B3: Name | C3: Department | D3: Attendance | R3: Salary Advance / Loan Details | V3: Gross Salary | W3: Payable Gross Salary | X3: Other Allownace | Y3: Salary.Actuals [Gross Salary - Leave Deduction] | Z3: Salary per day [Gross salary / no of days that month] | AA3: Basic [45% of Gross Salary] | AB3: Deductions | AJ3: Net Salary | AK3: QMIS Contribution | AM3: Remarks
D4: Total working days | E4: Lates. Actuals | F4: Lates. Leave [Exceeding lates conversions count] | G4: Final Lates after deducting exceeding Late leaves | H4: Permissions.Actuals | I4: Exceeding Permissions taken for this month | J4: Proper Permissions | K4: Proper Casual Leave already taken for this term | L4: Proper Casual Leave already taken for this year till date | M4: Exceeding Casual Leave taken for this month / Memo issued | N4: Absent / Suspension.Actuals | O4: Gardening / Other Leave | P4: Total Leave days.Actuals | Q4: Loss of Pay Days | R4: Total Loan Amount | S4: Amount already paid | T4: Amount to be paid for this month | U4: Remaining Loan Amount | AB4: Leave / Absent / Permission Leave / Late Leave | AC4: Not Punched Days | AD4: Not Punched LOP | AE4: Salary Advance / Loan | AF4: Special Deductions [Telephone Bill + Laptop + Uniform + Trainings etc] | AG4: PF [12% of Basic Salary] | AH4: ESI [0.75% of Salary.Actuals] | AI4: Total | AK4: PF [13.01% of Basic Salary] | AL4: ESI [3.25% of Salary.Actuals]
A5: 1 | B5: SUJATHA D/O SUBBURAM | C5: Director Academics | D5: 28 | E5: 0 | F5: =IF((E5/3)>=1,TRUNC(E5/3,0),0) -> 0 | G5: =E5-F5*3 -> 0 | H5: 0 | I5: =IF(H5<1,H5,H5-1) -> 0 | J5: =H5-I5 -> 0 | K5: =0+3+0.5 -> 3.5 | L5: 0 | M5: 0 | N5: 0 | O5: 0 | P5: =L5+M5+N5+O5 -> 0 | Q5: =(F5*0.5)+(I5*0.5)+M5+(N5*2) -> 0 | U5: =R5-(S5+T5) -> 0 | V5: 10000 | W5: =V5 -> 10000 | X5: 0 | Y5: =V5-AB5 -> 10000 | Z5: =V5/D5 -> 357.14286 | AA5: =V5*45% -> 4500 | AB5: =Q5*Z5 -> 0 | AD5: =(AC5)*Z5 -> 0 | AE5: =T5 -> 0 | AG5: 0 | AH5: 0 | AI5: =SUM(AB5:AH5) -> 0 | AJ5: =ROUND(SUM(W5:X5)-AI5,) -> 10000 | AN5: 1750063000000016
A6: 2 | B6: JOSEPHINE ANNE SHEEBHA ARULDASS | C6: Joint director Admin | D6: 28 | E6: 0 | F6: =IF((E6/3)>=1,TRUNC(E6/3,0),0) -> 0 | G6: =E6-F6*3 -> 0 | H6: 0 | I6: =IF(H6<1,H6,H6-1) -> 0 | J6: =H6-I6 -> 0 | K6: =3+0+3 -> 6 | L6: 0 | M6: 0 | N6: 0 | O6: 0 | P6: =L6+M6+N6+O6 -> 0 | Q6: =(F6*0.5)+(I6*0.5)+M6+(N6*2) -> 0 | U6: =R6-(S6+T6) -> 0 | V6: 10000 | W6: =V6 -> 10000 | X6: 0 | Y6: =V6-AB6 -> 10000 | Z6: =V6/D6 -> 357.14286 | AA6: =V6*45% -> 4500 | AB6: =Q6*Z6 -> 0 | AD6: =(AC6)*Z6 -> 0 | AE6: =T6 -> 0 | AG6: 0 | AH6: 0 | AI6: =SUM(AB6:AH6) -> 0 | AJ6: =ROUND(SUM(W6:X6)-AI6,) -> 10000 | AN6: 1750060000002726
A7: 3 | B7: G VAIYAPURI | C7: PRO | D7: 28 | E7: 0 | F7: =IF((E7/3)>=1,TRUNC(E7/3,0),0) -> 0 | G7: =E7-F7*3 -> 0 | H7: 0 | I7: =IF(H7<1,H7,H7-1) -> 0 | J7: =H7-I7 -> 0 | K7: =5+2.5+4.5 -> 12 | L7: 1 | M7: 0 | N7: 0 | O7: 0 | P7: =L7+M7+N7+O7 -> 1 | Q7: =(F7*0.5)+(I7*0.5)+M7+(N7*2) -> 0 | U7: =R7-(S7+T7) -> 0 | V7: 4000 | W7: =V7 -> 4000 | X7: 0 | Y7: =V7-AB7 -> 4000 | Z7: =V7/D7 -> 142.85714 | AA7: =V7*45% -> 1800 | AB7: =Q7*Z7 -> 0 | AD7: =(AC7)*Z7 -> 0 | AE7: =T7 -> 0 | AG7: 0 | AH7: 0 | AI7: =SUM(AB7:AH7) -> 0 | AJ7: =ROUND(SUM(W7:X7)-AI7,) -> 4000 | AN7: 1750061000000170
A8: 4 | B8: R SIVARANJANI | C8: Senior Accountant | D8: 28 | E8: 0 | F8: =IF((E8/3)>=1,TRUNC(E8/3,0),0) -> 0 | G8: =E8-F8*3 -> 0 | H8: 0 | I8: =IF(H8<1,H8,H8-1) -> 0 | J8: =H8-I8 -> 0 | K8: =5+5+4.5 -> 14.5 | L8: 0.5 | M8: 1.5 | N8: 0 | O8: 0 | P8: =L8+M8+N8+O8 -> 2 | Q8: =(F8*0.5)+(I8*0.5)+M8+(N8*2) -> 1.5 | U8: =R8-(S8+T8) -> 0 | V8: 10000 | W8: =V8 -> 10000 | X8: 0 | Y8: =V8-AB8 -> 9464.2857 | Z8: =V8/D8 -> 357.14286 | AA8: =V8*45% -> 4500 | AB8: =Q8*Z8 -> 535.71429 | AD8: =(AC8)*Z8 -> 0 | AE8: =T8 -> 0 | AG8: 0 | AH8: 0 | AI8: =SUM(AB8:AH8) -> 535.71429 | AJ8: =ROUND(SUM(W8:X8)-AI8,) -> 9464 | AN8: 1750061000000371
