Workbook

Sheet Overall - Top sheet
A1: QUEEN MIRA INTERNATIONAL SCHOOL
A2: TOP SHEET - SALARY STATEMENT JUNE 2026
A3: S. No | B3: Particulars | C3: No of Employees | D3: Gross Salary ( A ) | E3: Average Salary | F3: Deductions | L3: Net Salary [D] | M3: Employer Contribution | O3: Total [A+E+F]
F4: Late / Permission / Leave / Absent LOP | G4: Not Punched LOP | H4: Salary Advance / Loan | I4: Special Deductions [Telephone Bill + Laptop + Uniform + Trainings etc] | J4: PF 12% [B] | K4: ESI 0.75% [C] | M4: PF 13.01% [E] | N4: ESI 3.25% [F]
A5: 1 | B5: Academics Staff | C5: =Academics!#REF! -> #REF! | D5: =Academics!V7+Academics!X7 -> 172000 | E5: =D5/C5 -> #REF! | F5: =Academics!AB7 -> 0 | G5: =Academics!AD7 -> 0 | H5: =Academics!AE7 -> 12500 | I5: =Academics!AF7 -> 13799 | J5: =Academics!AG7 -> 1800 | K5: =Academics!AH7 -> 0 | L5: =Academics!AJ7 -> 102700 | M5: =Academics!AK7 -> 1951.5 | N5: =Academics!AL7 -> 0 | O5: =D5+M5+N5 -> 173951.5
A6: 2 | B6: Admin Staff | C6: =Admin!#REF! -> #REF! | D6: =Admin!V7+Admin!X7 -> 125000 | E6: =D6/C6 -> #REF! | F6: =Admin!AB7 -> 0 | G6: =Admin!AD7 -> 0 | H6: =Admin!AE7 -> 10000 | I6: =Admin!AF7 -> 21000 | J6: =Admin!AG7 -> 1800 | K6: =Admin!AH7 -> 0 | L6: =Admin!AJ7 -> 92200 | M6: =Admin!AK7 -> 1951.5 | N6: =Admin!AL7 -> 0 | O6: =D6+M6+N6 -> 126951.5
A7: 3 | B7: Drivers | C7: ='Relieved Admin'!#REF! -> #REF! | D7: =Drivers!V7 -> 46400 | E7: =D7/C7 -> #REF! | F7: =Drivers!AB7 -> 0 | G7: =Drivers!AD7 -> 0 | H7: =Drivers!AE7 -> 0 | I7: =Drivers!AF7 -> 2500 | J7: =Drivers!AG7 -> 2506 | K7: =Drivers!AH7 -> 172 | L7: =Drivers!AJ7 -> 41222 | M7: =Drivers!AK7 -> 2717 | N7: =Drivers!AL7 -> 745 | O7: =D7+M7+N7 -> 49862
A8: 4 | B8: Conductors | C8: =+Conductors!#REF! -> #REF! | D8: =Conductors!W7+Conductors!X7 -> 22300 | E8: =D8/C8 -> #REF! | F8: =Conductors!AB7 -> 0 | G8: =Conductors!AD7 -> 0 | H8: =Conductors!AE7 -> 0 | I8: =Conductors!AF7 -> 0 | J8: =Conductors!AG7 -> 697 | K8: =Conductors!AH7 -> 97 | L8: =Conductors!AJ7 -> 21506 | M8: =Conductors!AK7 -> 756 | N8: =Conductors!AL7 -> 420 | O8: =D8+M8+N8 -> 23476
A9: 5 | B9: Securities | C9: =Securities!#REF! -> #REF! | D9: =Securities!V7+Securities!X7 -> 44300 | E9: =D9/C9 -> #REF! | F9: =Securities!AB7 -> 416.66667 | G9: =Securities!AD7 -> 0 | H9: =Securities!AE7 -> 10000 | I9: =Securities!AF7 -> 0 | J9: =Securities!AG7 -> 0 | K9: =Securities!AH7 -> 0 | L9: =Securities!AJ7 -> 33883 | M9: =Securities!AK7 -> 0 | N9: =Securities!AL7 -> 0 | O9: =D9+M9+N9 -> 44300
A10: 6 | B10: Housekeeping | C10: =+'House Keeping'!#REF! -> #REF! | D10: ='House Keeping'!V7 -> 27800 | E10: =D10/C10 -> #REF! | F10: ='House Keeping'!AB7 -> 0 | G10: ='House Keeping'!AD7 -> 0 | H10: ='House Keeping'!AE7 -> 2000 | I10: ='House Keeping'!AF7 -> 0 | J10: ='House Keeping'!AG7 -> 1502 | K10: ='House Keeping'!AH7 -> 210 | L10: ='House Keeping'!AJ7 -> 24088 | M10: ='House Keeping'!AK7 -> 1629 | N10: ='House Keeping'!AL7 -> 904 | O10: =D10+M10+N10 -> 30333
A11: 7 | B11: Hostel | C11: =Hostel!A7 -> 3 | D11: =Hostel!V8 -> 40500 | E11: =D11/C11 -> 13500 | F11: =Hostel!AB8 -> 0 | G11: =Hostel!AD8 -> 0 | H11: =Hostel!AE8 -> 0 | I11: =Hostel!AF8 -> 0 | J11: =Hostel!AG8 -> 0 | K11: =Hostel!AH8 -> 0 | L11: =Hostel!AJ8 -> 40500 | M11: =Hostel!AK8 -> 0 | N11: =Hostel!AL8 -> 0 | O11: =D11+M11+N11 -> 40500
A12: 8 | B12: ECA | C12: =+'ECA '!A18 -> 14 | D12: =+'ECA '!D19 -> 221000 | E12: =D12/C12 -> 15785.714 | F12: =+'ECA '!K19 -> 4449.5968 | G12: 0 | H12: =+'ECA '!J19 -> 0 | I12: =+'ECA '!H19 -> 0 | J12: 0 | K12: 0 | L12: =+'ECA '!M19 -> 216551 | M12: 0 | N12: 0 | O12: =D12+M12+N12 -> 221000
A13: 9 | B13: Part Time - Academics | C13: =+'Part time academic'!A12 -> 11 | D13: =+'Part time academic'!D14 -> 286558.67 | E13: =D13/C13 -> 26050.788 | F13: =+'Part time academic'!I14 -> 666.66667 | G13: 0 | H13: 0 | I13: =+'Part time academic'!H14 -> 0 | J13: 0 | K13: 0 | L13: =+'Part time academic'!J14 -> 279225 | M13: 0 | N13: 0 | O13: =D13+M13+N13 -> 286558.67
A14: 10 | B14: Theni Upparpatti | C14: =+'Theni - Upparpatti'!#REF! -> #REF! | D14: ='Theni - Upparpatti'!V7 -> 20000 | E14: =D14/C14 -> #REF! | F14: ='Theni - Upparpatti'!AB7 -> 0 | G14: ='Theni - Upparpatti'!AD7 -> 0 | H14: ='Theni - Upparpatti'!AE7 -> 0 | I14: ='Theni - Upparpatti'!AF7 -> 0 | J14: ='Theni - Upparpatti'!AG7 -> 0 | K14: ='Theni - Upparpatti'!AH7 -> 0 | L14: ='Theni - Upparpatti'!AJ7 -> 20000 | M14: ='Theni - Upparpatti'!AK7 -> 0 | N14: ='Theni - Upparpatti'!AL7 -> 0 | O14: =D14+M14+N14 -> 20000
A15: 11 | B15: Academic Enrichment Program | C15: =+AEP!#REF! -> #REF! | D15: =+AEP!D6 -> 0 | E15: =D15/C15 -> #REF! | F15: =AEP!G6 -> 0 | I15: =AEP!F6 -> 0 | L15: =AEP!I6 -> 0 | O15: =D15+M15+N15 -> 0
A16: 12 | B16: Rifle Shooting | C16: =Rifle!A4 -> 1 | D16: =Rifle!D5 -> 66000 | E16: =D16/C16 -> 66000 | F16: =Rifle!J5 -> 0 | H16: =Rifle!H5 -> 0 | I16: =Rifle!F5 -> 0 | L16: =Rifle!L5 -> 66000 | O16: =D16+M16+N16 -> 66000
A17: 13 | B17: Part Time Admin | C17: ='Part Time - Admin'!A5 -> 2 | D17: ='Part Time - Admin'!D6 -> 35000 | E17: =D17/C17 -> 17500 | F17: ='Part Time - Admin'!L6 -> 0 | H17: 0 | I17: ='Part Time - Admin'!K6 -> 0 | L17: ='Part Time - Admin'!N6 -> 35000 | O17: =D17+M17+N17 -> 35000
A18: 14 | B18: Relieved Academics | C18: ='Relieved Academics'!A6 -> 2 | D18: ='Relieved Academics'!V7 -> 90000 | E18: 0 | F18: ='Relieved Academics'!AB7 -> 3000 | G18: ='Relieved Academics'!AD7 -> 0 | H18: ='Relieved Academics'!AE7 -> 0 | I18: ='Relieved Academics'!AF7 -> 4172 | J18: ='Relieved Academics'!AG7 -> 0 | K18: ='Relieved Academics'!AH7 -> 0 | L18: ='Relieved Academics'!AJ8 -> 46828 | M18: ='Relieved Academics'!AK7 -> 0 | N18: ='Relieved Academics'!AL7 -> 0 | O18: =D18+M18+N18 -> 90000
A19: 15 | B19: Relieved Admin | C19: ='Relieved Admin'!#REF! -> #REF! | D19: ='Relieved Admin'!V7 -> 34000 | E19: 0 | F19: ='Relieved Admin'!AB7 -> 0 | G19: ='Relieved Admin'!E7 -> 0 | H19: ='Relieved Admin'!AE7 -> 0 | I19: ='Relieved Admin'!AF7 -> 0 | J19: ='Relieved Admin'!AG7 -> 0 | K19: ='Relieved Admin'!AH7 -> 0 | L19: ='Relieved Admin'!AJ8 -> 9467 | M19: ='Relieved Admin'!AK7 -> 0 | N19: ='Relieved Admin'!AL7 -> 0 | O19: =D19+M19+N19 -> 34000
A20: Total | C20: =+C5+C6+C7+C8+C9+C10+2+12+12+3+1+2 -> #REF! | D20: =SUM(D5:D19) -> 1230858.7 | E20: =SUM(E5:E19) -> #REF! | F20: =SUM(F5:F19) -> 8532.9301 | G20: =SUM(G5:G19) -> 0 | H20: =SUM(H5:H19) -> 34500 | I20: =SUM(I5:I19) -> 41471 | J20: =SUM(J5:J19) -> 8305 | K20: =SUM(K5:K19) -> 479 | ... O20: =SUM(O5:O19) -> 1241932.7
A22: Payable Total (B+C+D+E+F) | O22: =J20+K20+L20+M20+N20 -> 1049028
A23: HR Manager | C23: Finance Manager | F23: Joint Director Admin | J23: Director Academics | N23: Managing Director

Sheet Academics
A1: QUEEN MIRA INTERNATIONAL SCHOOL
A2: ACADEMICS - SALARY STATEMENT JUNE 2026
A3: S.No | B3: Name | C3: Department | D3: Attendance | R3: Salary Advance / Loan Details | V3: Gross Salary | W3: Payable Gross Salary | X3: Other Allownace | Y3: Salary.Actuals [Gross Salary - Leave Deduction] | Z3: Salary per day [Gross salary / no of days that month] | AA3: Basic [45% of Gross Salary] | AB3: Deductions | AJ3: Net Salary | AK3: QMIS Contribution | AM3: Remarks
D4: Total working days | E4: Lates. Actuals | F4: Lates. Leave [Exceeding lates conversions count] | G4: Final Lates after deducting exceeding Late leaves | H4: Permissions.Actuals | I4: Exceeding Permissions taken for this month | J4: Proper Permissions | K4: Proper Casual Leave already taken for this year till date | L4: Proper Casual Leave taken for this month | M4: Exceeding Casual Leave taken for this month / Memo issued | N4: Absent / Suspension.Actuals | O4: Gardening / Other Leave | P4: Total Leave days.Actuals | Q4: Loss of Pay Days | R4: Total Loan Amount | S4: Amount already paid | T4: Amount to be paid for this month | U4: Remaining Loan Amount | AB4: Leave / Absent / Permission Leave / Late Leave | AC4: Not Punched Days | AD4: Not Punched LOP | AE4: Salary Advance / Loan | AF4: Special Deductions [Telephone Bill + healthcheck up + Uniform + Trainings etc] | AG4: PF [12% of Basic Salary] | AH4: ESI [0.75% of Salary.Actuals] | AI4: Total | AK4: PF [13.01% of Basic Salary] | AL4: ESI [3.25% of Salary.Actuals]
A5: 1 | B5: SUJATHA D/O SUBBURAM | C5: Director - Academics | D5: 30 | E5: 0 | F5: =IF((E5/3)>=1,TRUNC(E5/3,0),0) -> 0 | G5: =E5-F5*3 -> 0 | H5: 0 | I5: =IF(H5<1,H5,H5-1) -> 0 | J5: =H5-I5 -> 0 | K5: 0 | L5: 1.5 | M5: 0 | N5: 0 | O5: 0 | P5: =L5+M5+N5+O5 -> 1.5 | Q5: =(F5*0.5)+(I5*0.5)+M5+(N5*2) -> 0 | R5: =125000 -> 125000 | S5: =12500+12500+12500 -> 37500 | T5: 12500 | U5: =R5-(S5+T5) -> 75000 | V5: 130000 | W5: =V5 -> 130000 | X5: 0 | Y5: =W5-AB5 -> 130000 | Z5: =V5/D5 -> 4333.3333 | AA5: 15000 | AB5: =Q5*Z5 -> 0 | AD5: =(AC5)*Z5 -> 0 | AE5: =T5 -> 12500 | AF5: =2500+10000+500 -> 13000 | AG5: =(AA5*12%) -> 1800 | AH5: 0 | AI5: =SUM(AB5,AD5:AH5) -> 27300 | AJ5: =ROUND(SUM(W5:X5)-AI5,0) -> 102700 | AK5: =(AA5*13.01%) -> 1951.5 | AL5: 0 | AM5: Chit 4th month. Salary Adv Note: 4 Pg No: 36. | AN5: 1750155000050628
A6: 2 | B6: A JAINCOL FATHIMA | C6: Assistant Vice Principal Kinder Garten / PRT-English | D6: 30 | E6: 0 | F6: =IF((E6/3)>=1,TRUNC(E6/3,0),0) -> 0 | G6: =E6-F6*3 -> 0 | H6: 0 | I6: =IF(H6<1,H6,H6-1) -> 0 | J6: =H6-I6 -> 0 | K6: 0 | M6: 0 | N6: 0 | O6: 0 | P6: =L6+M6+N6+O6 -> 0 | Q6: =(F6*0.5)+(I6*0.5)+M6+(N6*2) -> 0 | R6: 0 | S6: 0 | T6: 0 | U6: =R6-(S6+T6) -> 0 | V6: 42000 | W6: =V6 -> 42000 | X6: 0 | Y6: =W6-AB6 -> 42000 | Z6: =V6/D6 -> 1400 | AA6: =W6*45% -> 18900 | AB6: =Q6*Z6 -> 0 | AC6: 0 | AD6: =(AC6)*Z6 -> 0 | AE6: =T6 -> 0 | AF6: =299+500 -> 799 | AG6: 0 | AH6: 0 | AI6: =SUM(AB6,AD6:AH6) -> 799 | AK6: 0 | AL6: 0 | AN6: 1750061000000064
R7: =SUM(R5:R6) -> 125000 | S7: =SUM(S5:S6) -> 37500 | T7: =SUM(T5:T6) -> 12500 | U7: =SUM(U5:U6) -> 75000 | V7: =SUM(V5:V6) -> 172000 | W7: =SUM(W5:W6) -> 172000 | X7: =SUM(X5:X6) -> 0 | Y7: =SUM(Y5:Y6) -> 172000 | ... AM7: =SUM(AM5:AM6) -> 0
A8: Note : An amount of ₹500 has already been deducted from your salary towards the Staff Planner Kit
A9: HR Manager | W9: Finance Manager | AL9: Director Academics

Sheet Relieved Academics
A1: QUEEN MIRA INTERNATIONAL SCHOOL
A2: ACADEMICS RELIEVED- SALARY STATEMENT JUNE 2026
A3: S.No | B3: Name | C3: Department | D3: Attendance | R3: Salary Advance / Loan Details | V3: Gross Salary | W3: Payable Gross Salary | X3: Other Allowance | Y3: Salary. Actuals [Gross Salary - Leave Deduction] | Z3: Salary per day [Gross salary / no of days that month] | AA3: Basic [45% of Gross Salary] | AB3: Deductions | AJ3: Net Salary | AK3: QMIS Contribution | AM3: Remarks
D4: Total working days | E4: Lates. Actuals | F4: Lates. Leave [Exceeding lates conversions count] | G4: Final Lates after deducting exceeding Late leaves | H4: Permissions. Actuals | I4: Exceeding Permissions taken for this month | J4: Proper Permissions | K4: Proper Casual Leave already taken for this year till date | L4: Proper Casual Leave taken for this month | M4: Exceeding Casual Leave taken for this month | N4: Absent / Suspension. Actuals | O4: Gardening / Other Leave | P4: Total Leave days. Actuals | Q4: Loss of Pay Days | R4: Total Loan Amount | S4: Amount already paid | T4: Amount to be paid for this month | U4: Remaining Loan Amount | AB4: Leave / Absent / Permission Leave / Late Leave | AC4: Not Punched Days | AD4: Not Punched LOP | AE4: Salary Advance / Loan | AF4: Special Deductions [Telephone Bill + Laptop + Uniform + Trainings etc] | AG4: PF [12% of Basic Salary] | AH4: ESI [0.75% of Salary. Actuals] | AI4: Total | AK4: PF [13.01% of Basic Salary] | AL4: ESI [3.25% of Salary. Actuals]
A5: 1 | B5: Rajasekar | C5: AEP Coordinator / Mentor Grade 9 to 12 | D5: 12 | E5: 0 | F5: =IF((E5/3)>=1,TRUNC(E5/3,0),0) -> 0 | G5: =E5-F5*3 -> 0 | H5: 0 | I5: =IF(H5<1,H5,H5-1) -> 0 | J5: =H5-I5 -> 0 | K5: 0 | L5: 1 | M5: 1.5 | N5: 0 | O5: 0 | P5: =L5+M5+N5+O5 -> 2.5 | Q5: =(F5*0.5)+(I5*0.5)+M5+(N5*2) -> 1.5 | U5: =R5-(S5+T5) -> 0 | V5: 60000 | W5: =V5/30*12 -> 24000 | Y5: =W5-AB5 -> 21000 | Z5: =V5/30 -> 2000 | AA5: =W5*45% -> 10800 | AB5: =Q5*Z5 -> 3000 | AD5: =(AC5)*Z5 -> 0 | AE5: =T5 -> 0 | AG5: 0 | AH5: 0 | AI5: =SUM(AB5,AD5:AH5) -> 3000 | AJ5: =ROUND(SUM(W5:X5)-AI5,0) -> 21000 | AM5: As per MD's Intrcution Lates Not Considered. Relieved on 12/06/2026 | AN5: 1750060000003764
A6: 2 | B6: R Veerachinna Krishnan | C6: TGT - Hindi | D6: 30 | E6: 1 | F6: =IF((E6/3)>=1,TRUNC(E6/3,0),0) -> 0 | G6: =E6-F6*3 -> 1 | H6: 0 | I6: =IF(H6<1,H6,H6-1) -> 0 | J6: =H6-I6 -> 0 | K6: 0 | L6: 2 | M6: 0 | N6: 0 | O6: 0 | P6: =L6+M6+N6+O6 -> 2 | Q6: =(F6*0.5)+(I6*0.5)+M6+(N6*2) -> 0 | U6: =R6-(S6+T6) -> 0 | V6: 30000 | W6: =V6 -> 30000 | Y6: =W6-AB6 -> 30000 | Z6: =V6/D6 -> 1000 | AA6: =W6*45% -> 13500 | AB6: =Q6*Z6 -> 0 | AD6: =(AC6)*Z6 -> 0 | AE6: =T6 -> 0 | AF6: =1043*4 -> 4172 | AG6: 0 | AH6: 0 | AI6: =SUM(AB6,AD6:AH6) -> 4172 | AJ6: =ROUND(SUM(W6:X6)-AI6,0) -> 25828 | AM6: Uniform 2/6 deduction. Relieved on 30.06.2026 .Uniform Full amount deducted | AN6: 1750060000003788
A7: TOTAL | R7: =SUM(R5:R6) -> 0 | S7: =SUM(S5:S6) -> 0 | T7: =SUM(T5:T6) -> 0 | U7: =SUM(U5:U6) -> 0 | V7: =SUM(V5:V6) -> 90000 | W7: =SUM(W5:W6) -> 54000 | X7: =SUM(X5:X6) -> 0 | Y7: =SUM(Y5:Y6) -> 51000 | ... AL7: =SUM(AL5:AL6) -> 0
AD8: Payable salary | AJ8: =+AJ7 -> 46828
A9: HR Manager | U9: Finance Manager | AK9: Director Academics

Sheet Admin
A1: QUEEN MIRA INTERNATIONAL SCHOOL
A2: ADMIN - SALARY STATEMENT JUNE 2026
A3: S.No | B3: Name | C3: Department | D3: Attendance | R3: Salary Advance / Loan Details | V3: Gross Salary | W3: Payable Gross Salary | X3: Other Allownace | Y3: Salary.Actuals [Gross Salary - Leave Deduction] | Z3: Salary per day [Gross salary / no of days that month] | AA3: Basic [45% of Gross Salary] | AB3: Deductions | AJ3: Net Salary | AK3: QMIS Contribution | AM3: Remarks
D4: Total working days | E4: Lates. Actuals | F4: Lates. Leave [Exceeding lates conversions count] | G4: Final Lates after deducting exceeding Late leaves | H4: Permissions.Actuals | I4: Exceeding Permissions taken for this month | J4: Proper Permissions | K4: Proper Casual Leave already taken for this year till date | L4: Proper Casual Leave taken for this month | M4: Exceeding Casual Leave taken for this month / Memo issued | N4: Absent / Suspension.Actuals | O4: Gardening / Other Leave | P4: Total Leave days.Actuals | Q4: Loss of Pay Days | R4: Total Loan Amount | S4: Amount already paid | T4: Amount to be paid for this month | U4: Remaining Loan Amount | AB4: Leave / Absent / Permission Leave / Late Leave | AC4: Not Punched Days | AD4: Not Punched LOP | AE4: Salary Advance / Loan | AF4: Special Deductions [Telephone Bill + healthcheck up + Uniform + Trainings etc] | AG4: PF [12% of Basic Salary] | AH4: ESI [0.75% of Salary.Actuals] | AI4: Total | AK4: PF [13.01% of Basic Salary] | AL4: ESI [3.25% of Salary.Actuals]
A5: 1 | B5: JOSEPHINE ANNE SHEEBHA ARULDASS | C5: Joint Director- Admin | D5: 30 | E5: 0 | F5: =IF((E5/3)>=1,TRUNC(E5/3,0),0) -> 0 | G5: =E5-F5*3 -> 0 | H5: 0 | I5: =IF(H5<1,H5,H5-1) -> 0 | J5: =H5-I5 -> 0 | K5: 0 | L5: 0.5 | M5: 0 | N5: 0 | O5: 0 | P5: =L5+M5+N5+O5 -> 0.5 | Q5: =(F5*0.5)+(I5*0.5)+M5+(N5*2) -> 0 | R5: =100000+100000+50000 -> 250000 | S5: =10000+10000+10000+10000+10000+10000+10000+10000+10000+10000+10000 -> 110000 | T5: 10000 | U5: =R5-(S5+T5) -> 130000 | V5: 100000 | W5: =V5 -> 100000 | X5: 0 | Y5: =W5-AB5 -> 100000 | Z5: =V5/D5 -> 3333.3333 | AA5: 15000 | AB5: =Q5*Z5 -> 0 | AD5: =(AC5)*Z5 -> 0 | AE5: =T5 -> 10000 | AF5: =10000+10000+500 -> 20500 | AG5: =(AA5*12%) -> 1800 | AH5: 0 | AI5: =SUM(AB5,AD5:AH5) -> 32300 | AJ5: =ROUND(SUM(W5:X5)-AI5,0) -> 67700 | AK5: =(AA5*13.01%) -> 1951.5 | AL5: 0 | AM5: 5,000 will be given as cash. Salary Adv Note :4 Pg No. 19. Chit 4th month | AN5: 1750062000000072
A6: 2 | B6: Jeya Dharini Abinath | C6: GM - Finance | D6: 30 | E6: 0 | F6: =IF((E6/3)>=1,TRUNC(E6/3,0),0) -> 0 | G6: =E6-F6*3 -> 0 | H6: 0 | I6: =IF(H6<1,H6,H6-1) -> 0 | J6: =H6-I6 -> 0 | K6: 0 | L6: 0 | M6: 0 | N6: 0 | O6: 0 | P6: =L6+M6+N6+O6 -> 0 | Q6: =(F6*0.5)+(I6*0.5)+M6+(N6*2) -> 0 | U6: =R6-(S6+T6) -> 0 | V6: 25000 | W6: =V6 -> 25000 | X6: 0 | Y6: =W6-AB6 -> 25000 | Z6: =V6/D6 -> 833.33333 | AA6: =W6*45% -> 11250 | AB6: =Q6*Z6 -> 0 | AD6: =(AC6)*Z6 -> 0 | AE6: =T6 -> 0 | AF6: 500 | AG6: 0 | AH6: 0 | AI6: =SUM(AB6,AD6:AH6) -> 500 | AJ6: =ROUND(SUM(W6:X6)-AI6,0) -> 24500 | AK6: 0 | AL6: 0
R7: =SUM(R5:R6) -> 250000 | S7: =SUM(S5:S6) -> 110000 | T7: =SUM(T5:T6) -> 10000 | U7: =SUM(U5:U6) -> 130000 | V7: =SUM(V5:V6) -> 125000 | W7: =SUM(W5:W6) -> 125000 | X7: =SUM(X5:X6) -> 0 | Y7: =SUM(Y5:Y6) -> 125000 | ... AL7: =SUM(AL5:AL6) -> 0
A8: Note : An amount of ₹500 has already been deducted from your salary towards the Staff Planner Kit
A9: HR Manager | W9: Finance Manager | AL9: Joint Director - Admin
G15: =43-15 -> 28

Sheet Relieved Admin
A1: QUEEN MIRA INTERNATIONAL SCHOOL
A2: ADMIN RELIEVED - SALARY STATEMENT JUNE 2026
A3: S.No | B3: Name | C3: Department | D3: Attendance | R3: Salary Advance / Loan Details | V3: Gross Salalry | W3: Payable Gross Salary | X3: Other Allownace | Y3: Salary.Actuals [Gross Salary - Leave Deduction] | Z3: Salary per day [Gross salary / no of days that month] | AA3: Basic [45% of Gross Salary] | AB3: Deductions | AJ3: Net Salary | AK3: QMIS Contribution | AM3: Remarks
D4: Total working days | E4: Lates. Actuals | F4: Lates. Leave [Exceeding lates conversions count] | G4: Final Lates after deducting exceeding Late leaves | H4: Permissions.Actuals | I4: Exceeding Permissions taken for this month | J4: Proper Permissions | K4: Proper Casual Leave already taken for this year till date | L4: Proper Casual Leave taken for this month | M4: Exceeding Casual Leave taken for this month | N4: Absent / Suspension.Actuals | O4: Gardening / Other Leave | P4: Total Leave days.Actuals | Q4: Loss of Pay Days | R4: Total Loan Amount | S4: Amount already paid | T4: Amount to be paid for this month | U4: Remaining Loan Amount | AB4: Leave / Absent / Permission Leave / Late Leave | AC4: Not Punched Days | AD4: Not Punched LOP | AE4: Salary Advance / Loan | AF4: Special Deductions [Telephone Bill + Laptop + Uniform + Trainings etc] | AG4: PF [12% of Basic Salary] | AH4: ESI [0.75% of Salary.Actuals] | AI4: Total | AK4: PF [13.01% of Basic Salary] | AL4: ESI [3.25% of Salary.Actuals]
A5: 1 | B5: DEEPIKA KANNAN | C5: Accountant | D5: 10 | E5: 0 | F5: =IF((E5/3)>=1,TRUNC(E5/3,0),0) -> 0 | G5: =E5-F5*3 -> 0 | H5: 0 | I5: =IF(H5<1,H5,H5-1) -> 0 | J5: =H5-I5 -> 0 | K5: 0 | L5: 1 | M5: 0 | N5: 0 | O5: 0 | P5: =L5+M5+N5+O5 -> 1 | Q5: =(F5*0.5)+(I5*0.5)+M5+(N5*2) -> 0 | U5: =R5-(S5+T5) -> 0 | V5: 20000 | W5: =V5/30*10 -> 6666.6667 | Y5: =W5-AB5 -> 6666.6667 | Z5: =V5/30 -> 666.66667 | AA5: =W5*45% -> 3000 | AB5: =Q5*Z5 -> 0 | AD5: =(AC5)*Z5 -> 0 | AE5: =T5 -> 0 | AG5: 0 | AH5: 0 | AI5: =SUM(AB5,AD5:AH5) -> 0 | AJ5: =ROUND(SUM(W5:X5)-AI5,0) -> 6667 | AK5: 0 | AL5: 0 | AM5: Relived on 10/06/2026 | AN5: 1750060000000023
A6: 2 | B6: G B Hemavathy | C6: Executive Audit | D6: 6 | E6: 0 | F6: =IF((E6/3)>=1,TRUNC(E6/3,0),0) -> 0 | G6: =E6-F6*3 -> 0 | H6: 0 | I6: =IF(H6<1,H6,H6-1) -> 0 | J6: =H6-I6 -> 0 | K6: 0 | L6: 0 | M6: 0 | N6: 0 | O6: 0 | P6: =L6+M6+N6+O6 -> 0 | Q6: =(F6*0.5)+(I6*0.5)+M6+(N6*2) -> 0 | U6: =R6-(S6+T6) -> 0 | V6: 14000 | W6: =V6/30*6 -> 2800 | X6: 0 | Y6: =W6-AB6 -> 2800 | Z6: =V6/30 -> 466.66667 | AA6: =W6*45% -> 1260 | AB6: =Q6*Z6 -> 0 | AD6: =(AC6)*Z6 -> 0 | AE6: =T6 -> 0 | AF6: 0 | AG6: 0 | AH6: 0 | AI6: =SUM(AB6,AD6:AH6) -> 0 | AJ6: =ROUND(SUM(W6:X6)-AI6,0) -> 2800 | AN6: 1750061000000572
A7: TOTAL | R7: =SUM(R5:R6) -> 0 | S7: =SUM(S5:S6) -> 0 | T7: =SUM(T5:T6) -> 0 | U7: =SUM(U5:U6) -> 0 | V7: =SUM(V5:V6) -> 34000 | W7: =SUM(W5:W6) -> 9466.6667 | X7: =SUM(X5:X6) -> 0 | Y7: =SUM(Y5:Y6) -> 9466.6667 | ... AL7: =SUM(AL5:AL6) -> 0
AD8: Payable salary | AJ8: =+AJ7 -> 9467
A9: HR Manager | U9: Finance Manager | AK9: Joint Director-Admin

Sheet Drivers
A1: QUEEN MIRA INTERNATIONAL SCHOOL
A2: DRIVERS - SALARY STATEMENT JUNE 2026
A3: S.No | B3: Name | C3: Department | D3: Attendance | R3: Salary Advance / Loan Details | V3: Gross Salary | W3: Payable Gross Salary | X3: Other Allownace | Y3: Salary.Actuals [Gross Salary - Leave Deduction] | Z3: Salary per day [Gross salary / no of days that month] | AA3: Basic [45% of Payable Gross Salary] | AB3: Deductions | AJ3: Net Salary | AK3: QMIS Contribution | AM3: Remarks
D4: Total working days | E4: Lates. Actuals | F4: Lates. Leave [Exceeding lates conversions count] | G4: Final Lates after deducting exceeding Late leaves | H4: Permissions.Actuals | I4: Exceeding Permissions taken for this month | J4: Proper Permissions | K4: Proper Casual Leave already taken for this year till date | L4: Proper Casual Leave taken for this month | M4: Exceeding Casual Leave taken for this month / Memo issued | N4: Absent / Suspension.Actuals | O4: Gardening / Other Leave | P4: Total Leave days.Actuals | Q4: Loss of Pay Days | R4: Total Loan Amount | S4: Amount already paid | T4: Amount to be paid for this month | U4: Remaining Loan Amount | AB4: Leave / Absent / Permission Leave / Late Leave | AC4: Not Punched Days | AD4: Not Punched LOP | AE4: Salary Advance / Loan | AF4: Special Deductions [Telephone Bill + healthcheck up + Uniform + Trainings etc] | AG4: PF [12% of Basic Salary] | AH4: ESI [0.75% of Salary.Actuals] | AI4: Total | AK4: PF [13.01% of Basic Salary] | AL4: ESI [3.25% of Salary.Actuals]
A5: 1 | B5: KUMARAVEL MOOKKAIAH | C5: Transport Driver | D5: 30 | E5: 0 | F5: =IF((E5/3)>=1,TRUNC(E5/3,0),0) -> 0 | G5: =E5-F5*3 -> 0 | H5: 0 | I5: =IF(H5<2,H5,H5-2) -> 0 | J5: =H5-I5 -> 0 | K5: 0 | L5: 1.5 | M5: 0 | N5: 0 | O5: 0 | P5: =L5+M5+N5+O5 -> 1.5 | Q5: =(F5*0.5)+(I5*0.5)+M5+(N5*2) -> 0 | U5: =R5-(S5+T5) -> 0 | V5: 23500 | W5: =V5 -> 23500 | X5: 0 | Y5: =(W5+X5)-AB5 -> 23500 | Z5: =(W5+X5)/D5 -> 783.33333 | AA5: =W5*45% -> 10575 | AB5: =Q5*Z5 -> 0 | AD5: =(AC5)*Z5 -> 0 | AE5: =T5 -> 0 | AG5: =ROUNDUP(AA5*12%,0) -> 1269 | AH5: 0 | AI5: =SUM(AB5,AD5:AH5) -> 1269 | AJ5: =ROUND(SUM(W5:X5)-AI5,0) -> 22231 | AK5: =ROUNDUP(AA5*13.01%,0) -> 1376 | AL5: 0 | AN5: 1750060000000508
A6: 2 | B6: DURAIMURUGAN NAGARAJAN | C6: Transport Driver | D6: 30 | E6: 0 | F6: =IF((E6/3)>=1,TRUNC(E6/3,0),0) -> 0 | G6: =E6-F6*3 -> 0 | H6: 0 | I6: =IF(H6<1,H6,H6-1) -> 0 | J6: =H6-I6 -> 0 | K6: 0 | L6: 2 | M6: 0 | N6: 0 | O6: 0 | P6: =L6+M6+N6+O6 -> 2 | Q6: =(F6*0.5)+(I6*0.5)+M6+(N6*2) -> 0 | U6: =R6-(S6+T6) -> 0 | V6: 22900 | W6: =V6 -> 22900 | Y6: =(W6+X6)-AB6 -> 22900 | Z6: =(W6+X6)/D6 -> 763.33333 | AA6: =W6*45% -> 10305 | AB6: =Q6*Z6 -> 0 | AD6: =(AC6)*Z6 -> 0 | AE6: =T6 -> 0 | AF6: 2500 | AG6: =ROUNDUP(AA6*12%,0) -> 1237 | AH6: =ROUNDUP((Y6+X6)*0.75%,0) -> 172 | AI6: =SUM(AB6,AD6:AH6) -> 3909 | AJ6: =ROUND(SUM(W6:X6)-AI6,0) -> 18991 | AK6: =ROUNDUP(AA6*13.01%,0) -> 1341 | AL6: =ROUNDUP((Y6+X6)*3.25%,0) -> 745 | AM6: Chit 4th month | AN6: 1750060000000522
A7: TOTAL | R7: =SUM(R5:R6) -> 0 | S7: =SUM(S5:S6) -> 0 | T7: =SUM(T5:T6) -> 0 | U7: =SUM(U5:U6) -> 0 | V7: =SUM(V5:V6) -> 46400 | W7: =SUM(W5:W6) -> 46400 | X7: =SUM(X5:X6) -> 0 | Y7: =SUM(Y5:Y6) -> 46400 | ... AL7: =SUM(AL5:AL6) -> 745
A8: HR Manager | U8: Finance Manager | AL8: Joint Director - Admin

Sheet Conductors
A1: QUEEN MIRA INTERNATIONAL SCHOOL
A2: CONDUCTORS - SALARY STATEMENT JUNE 2026
A3: S.No | B3: Name | C3: Department | D3: Attendance | R3: Salary Advance / Loan Details | V3: Gross Salary | W3: Payable Gross Salary | X3: Other Allownace | Y3: Salary Actuals [Gross Salary - Leave Deduction] | Z3: Salary per day [Gross salary / no of days that month] | AA3: Basic [45% of Gross Salary] | AB3: Deductions | AJ3: Net Salary | AK3: QMIS Contribution | AM3: Remarks
D4: Total working days | E4: Lates. Actuals | F4: Lates. Leave [Exceeding lates conversions count] | G4: Final Lates after deducting exceeding Late leaves | H4: Permissions.Actuals | I4: Exceeding Permissions taken for this month | J4: Proper Permissions | K4: Proper Casual Leave already taken for this year till date | L4: Proper Casual Leave taken for this month | M4: Exceeding Casual Leave taken for this month / Memo issued | N4: Absent / Suspension.Actuals | O4: Gardening / Other Leave | P4: Total Leave days.Actuals | Q4: Loss of Pay Days | R4: Total Loan Amount | S4: Amount already paid | T4: Amount to be paid for this month | U4: Remaining Loan Amount | AB4: Leave / Absent / Permission Leave / Late Leave | AC4: Not Punched Days | AD4: Not Punched LOP | AE4: Salary Advance / Loan | AF4: Special Deductions [Telephone Bill + Laptop + Uniform + Trainings etc] | AG4: PF [12% of Basic Salary] | AH4: ESI [0.75% of Salary.Actuals] | AI4: Total | AK4: PF [13.01% of Basic Salary] | AL4: ESI [3.25% of Salary.Actuals]
A5: 1 | B5: SUNDARI JEYARAM | C5: Conductor | D5: 30 | E5: 0 | F5: =IF((E5/3)>=1,TRUNC(E5/3,0),0) -> 0 | G5: =E5-F5*3 -> 0 | H5: 0 | I5: =IF(H5<2,H5,H5-2) -> 0 | J5: =H5-I5 -> 0 | K5: 0 | L5: 0.5 | M5: 0 | N5: 0 | O5: 0 | P5: =L5+M5+N5+O5 -> 0.5 | Q5: =(F5*0.5)+(I5*0.5)+M5+(N5*2) -> 0 | R5: 0 | S5: 0 | T5: 0 | U5: =R5-(S5+T5) -> 0 | V5: 9400 | W5: =V5 -> 9400 | Y5: =(W5+X5)-AB5 -> 9400 | Z5: =(W5+X5)/D5 -> 313.33333 | AA5: =W5*45% -> 4230 | AB5: =Q5*Z5 -> 0 | AC5: 0 | AD5: =(AC5)*Z5 -> 0 | AE5: =T5 -> 0 | AG5: 0 | AH5: 0 | AI5: =SUM(AB5,AD5:AH5) -> 0 | AJ5: =ROUND(SUM(W5:X5)-AI5,0) -> 9400 | AK5: 0 | AL5: 0 | AN5: 1750059000000054
A6: 2 | B6: S CHITRA | C6: Conductor | D6: 30 | E6: 0 | F6: =IF((E6/3)>=1,TRUNC(E6/3,0),0) -> 0 | G6: =E6-F6*3 -> 0 | H6: 2 | I6: =IF(H6<2,H6,H6-2) -> 0 | J6: =H6-I6 -> 2 | K6: 0 | L6: 1 | M6: 0 | N6: 0 | O6: 0 | P6: =L6+M6+N6+O6 -> 1 | Q6: =(F6*0.5)+(I6*0.5)+M6+(N6*2) -> 0 | R6: 0 | S6: 0 | T6: 0 | U6: =R6-(S6+T6) -> 0 | V6: 12900 | W6: =V6 -> 12900 | Y6: =(W6+X6)-AB6 -> 12900 | Z6: =(W6+X6)/D6 -> 430 | AA6: =W6*45% -> 5805 | AB6: =Q6*Z6 -> 0 | AD6: =(AC6)*Z6 -> 0 | AE6: =T6 -> 0 | AG6: =ROUNDUP(AA6*12%,0) -> 697 | AH6: =ROUNDUP((Y6+X6)*0.75%,0) -> 97 | AI6: =SUM(AB6,AD6:AH6) -> 794 | AJ6: =ROUND(SUM(W6:X6)-AI6,0) -> 12106 | AK6: =ROUNDUP(AA6*13.01%,0) -> 756 | AL6: =ROUNDUP((Y6+X6)*3.25%,0) -> 420 | AN6: 1750059000000281
A7: TOTAL | R7: =SUM(R5:R6) -> 0 | S7: =SUM(S5:S6) -> 0 | T7: =SUM(T5:T6) -> 0 | U7: =SUM(U5:U6) -> 0 | V7: =SUM(V5:V6) -> 22300 | W7: =SUM(W5:W6) -> 22300 | X7: =SUM(X5:X6) -> 0 | Y7: =SUM(Y5:Y6) -> 22300 | ... AM7: =SUM(AM5:AM6) -> 0 | AO7: =SUM(AO5:AO6) -> 0
A8: HR Manager | U8: Finance Manager | AL8: Joint Director - Admin

Sheet Securities
A1: QUEEN MIRA INTERNATIONAL SCHOOL
A2: SECURITIES - SALARY STATEMENT JUNE 2026
A3: S.No | B3: Name | C3: Department | D3: Attendance | R3: Salary Advance / Loan Details | V3: Gross Salary | W3: Payable Gross Salary | X3: Other Allownace | Y3: Salary.Actuals [Gross Salary - Leave Deduction] | Z3: Salary per day [Gross salary / no of days that month] | AA3: Basic [45% of Gross Salary] | AB3: Deductions | AJ3: Net Salary | AK3: QMIS Contribution | AM3: Remarks
D4: Total working days | E4: Lates. Actuals | F4: Lates. Leave [Exceeding lates conversions count] | G4: Final Lates after deducting exceeding Late leaves | H4: Permissions.Actuals | I4: Exceeding Permissions taken for this month | J4: Proper Permissions | K4: Proper Casual Leave already taken for this year till date | L4: Proper Casual Leave taken for this month | M4: Exceeding Casual Leave taken for this month / Memo issued | N4: Absent / Suspension.Actuals | O4: Gardening / Other Leave | P4: Total Leave days.Actuals | Q4: Loss of Pay Days | R4: Total Loan Amount | S4: Amount already paid | T4: Amount to be paid for this month | U4: Remaining Loan Amount | AB4: Leave / Absent / Permission Leave / Late Leave | AC4: Not Punched Days | AD4: Not Punched LOP | AE4: Salary Advance / Loan | AF4: Special Deductions [Telephone Bill + Laptop + Uniform + Trainings etc] | AG4: PF [12% of Basic Salary] | AH4: ESI [0.75% of Salary.Actuals] | AI4: Total | AK4: PF [13.01% of Basic Salary] | AL4: ESI [3.25% of Salary.Actuals]
A5: 1 | B5: VAIRAMANI S/O BOSE | C5: Child Safety Officer | D5: 30 | E5: 0 | F5: =IF((E5/3)>=1,TRUNC(E5/3,0),0) -> 0 | G5: =E5-F5*3 -> 0 | H5: 2 | I5: =IF(H5<2,H5,H5-2) -> 0 | J5: =H5-I5 -> 2 | K5: 0 | L5: 0.5 | M5: 0 | N5: 0 | O5: 0 | P5: =L5+M5+N5+O5 -> 0.5 | Q5: =(F5*0.5)+(I5*0.5)+L5+(N5*2)+M5 -> 0.5 | R5: =150000+200000+50000 -> 400000 | S5: =87000+10000+10000+10000+10000+10000+10000+10000+10000+10000+10000+10000+10000+10000+10000+10000+10000+10000 -> 257000 | T5: 10000 | U5: =R5-(S5+T5) -> 133000 | V5: 25000 | W5: =V5 -> 25000 | X5: 0 | Y5: =W5-AB5 -> 24583.333 | Z5: =W5/D5 -> 833.33333 | AA5: =W5*45% -> 11250 | AB5: =Q5*Z5 -> 416.66667 | AD5: =(AC5)*Z5 -> 0 | AE5: =T5 -> 10000 | AG5: 0 | AH5: 0 | AI5: =SUM(AB5,AD5:AH5) -> 10416.667 | AJ5: =ROUND(SUM(W5:X5)-AI5,0) -> 14583 | AK5: 0 | AL5: 0 | AM5: Salary Adv Note 4 Pg.No: 7. | AN5: 1750059000000196
A6: 2 | B6: MOHAMED ALI JINNA A | C6: Security Officer | D6: 30 | E6: 0 | F6: =IF((E6/3)>=1,TRUNC(E6/3,0),0) -> 0 | G6: =E6-F6*3 -> 0 | H6: 2 | I6: =IF(H6<2,H6,H6-2) -> 0 | J6: =H6-I6 -> 2 | K6: 0 | L6: 0 | M6: 0 | N6: 0 | O6: 0 | P6: =L6+M6+N6+O6 -> 0 | Q6: =(F6*0.5)+(I6*0.5)+L6+(N6*2)+M6 -> 0 | U6: =R6-(S6+T6) -> 0 | V6: 19300 | W6: =V6 -> 19300 | X6: 0 | Y6: =W6-AB6 -> 19300 | Z6: =W6/D6 -> 643.33333 | AA6: =W6*45% -> 8685 | AB6: =Q6*Z6 -> 0 | AD6: =(AC6)*Z6 -> 0 | AE6: =T6 -> 0 | AG6: 0 | AH6: 0 | AI6: =SUM(AB6,AD6:AH6) -> 0 | AJ6: =ROUND(SUM(W6:X6)-AI6,0) -> 19300 | AK6: 0 | AL6: 0 | AN6: 1750060000000380
A7: TOTAL | R7: =SUM(R5:R6) -> 400000 | S7: =SUM(S5:S6) -> 257000 | T7: =SUM(T5:T6) -> 10000 | U7: =SUM(U5:U6) -> 133000 | V7: =SUM(V5:V6) -> 44300 | W7: =SUM(W5:W6) -> 44300 | X7: =SUM(X5:X6) -> 0 | Y7: =SUM(Y5:Y6) -> 43883.333 | ... AM7: =SUM(AM5:AM6) -> 0
A8: HR Manager | U8: Finance Manager | AL8: Joint Director - Admin

Sheet House Keeping
A1: QUEEN MIRA INTERNATIONAL SCHOOL
A2: HOUSE KEEPING - SALARY STATEMENT JUNE 2026
A3: S.No | B3: Name | C3: Department | D3: Attendance | R3: Salary Advance / Loan Details | V3: Gross Salary | W3: Payable Gross Salary | X3: Other Allownace | Y3: Salary.Actuals [Gross Salary - Leave Deduction] | Z3: Salary per day [Gross salary / no of days that month] | AA3: Basic [45% of Gross Salary] | AB3: Deductions | AJ3: Net Salary | AK3: QMIS Contribution | AM3: Remarks
D4: Total working days | E4: Lates. Actuals | F4: Lates. Leave [Exceeding lates conversions count] | G4: Final Lates after deducting exceeding Late leaves | H4: Permissions.Actuals | I4: Exceeding Permissions taken for this month | J4: Proper Permissions | K4: Proper Casual Leave already taken for this year till date | L4: Proper Casual Leave taken for this month | M4: Exceeding Casual Leave taken for this month / Memo issued | N4: Absent / Suspension.Actuals | O4: Gardening / Other Leave | P4: Total Leave days.Actuals | Q4: Loss of Pay Days | R4: Total Loan Amount | S4: Amount already paid | T4: Amount to be paid for this month | U4: Remaining Loan Amount | AB4: Leave / Absent / Permission Leave / Late Leave | AC4: Not Punched Days | AD4: Not Punched LOP | AE4: Salary Advance / Loan | AF4: Special Deductions [Telephone Bill + Laptop + Uniform + Trainings etc] | AG4: PF [12% of Basic Salary] | AH4: ESI [0.75% of Salary.Actuals] | AI4: Total | AK4: PF [13.01% of Basic Salary] | AL4: ESI [3.25% of Salary.Actuals]
A5: 1 | B5: AMARAVALLI W/O RAJANGAM | C5: Janitor | D5: 30 | E5: 0 | F5: =IF((E5/3)>=1,TRUNC(E5/3,0),0) -> 0 | G5: =E5-F5*3 -> 0 | H5: 0 | I5: =IF(H5<1,H5,H5-1) -> 0 | J5: =H5-I5 -> 0 | K5: 0 | L5: 0 | M5: 0 | N5: 0 | O5: 0 | P5: =L5+M5+N5+O5 -> 0 | Q5: =(F5*0.5)+(I5*0.5)+M5+(N5*2) -> 0 | U5: =R5-(S5+T5) -> 0 | V5: 14300 | W5: =V5 -> 14300 | Y5: =(W5+X5)-AB5 -> 14300 | Z5: =W5/D5 -> 476.66667 | AA5: =W5*45% -> 6435 | AB5: =Q5*Z5 -> 0 | AD5: =(AC5)*Z5 -> 0 | AE5: =T5 -> 0 | AG5: =ROUNDUP(AA5*12%,0) -> 773 | AH5: =ROUNDUP((Y5+X5)*0.75%,0) -> 108 | AI5: =SUM(AB5,AD5:AH5) -> 881 | AJ5: =ROUND(SUM(W5:X5)-AI5,0) -> 13419 | AK5: =ROUNDUP(AA5*13.01%,0) -> 838 | AL5: =ROUNDUP((Y5+X5)*3.25%,0) -> 465 | AN5: 1750060000000886
A6: 2 | B6: PARVATHI W/O MUTHAIAH | C6: Janitor | D6: 30 | E6: 0 | F6: =IF((E6/3)>=1,TRUNC(E6/3,0),0) -> 0 | G6: =E6-F6*3 -> 0 | H6: 0 | I6: =IF(H6<2,H6,H6-2) -> 0 | J6: =H6-I6 -> 0 | K6: 0 | L6: 1 | M6: 0 | N6: 0 | O6: 0 | P6: =L6+M6+N6+O6 -> 1 | Q6: =(F6*0.5)+(I6*0.5)+M6+(N6*2) -> 0 | R6: 20000 | S6: =2000+2000+2000+2000+2000+2000+2000 -> 14000 | T6: 2000 | U6: =R6-(S6+T6) -> 4000 | V6: 13500 | W6: =V6 -> 13500 | Y6: =(W6+X6)-AB6 -> 13500 | Z6: =W6/D6 -> 450 | AA6: =W6*45% -> 6075 | AB6: =Q6*Z6 -> 0 | AD6: =(AC6)*Z6 -> 0 | AE6: =T6 -> 2000 | AG6: =ROUNDUP(AA6*12%,0) -> 729 | AH6: =ROUNDUP((Y6+X6)*0.75%,0) -> 102 | AI6: =SUM(AB6,AD6:AH6) -> 2831 | AJ6: =ROUND(SUM(W6:X6)-AI6,0) -> 10669 | AK6: =ROUNDUP(AA6*13.01%,0) -> 791 | AL6: =ROUNDUP((Y6+X6)*3.25%,0) -> 439 | AM6: Salary Adv Note: 4Pg.No: 30 | AN6: 1750059000000231
A7: TOTAL | R7: =SUM(R5:R6) -> 20000 | S7: =SUM(S5:S6) -> 14000 | T7: =SUM(T5:T6) -> 2000 | U7: =SUM(U5:U6) -> 4000 | V7: =SUM(V5:V6) -> 27800 | W7: =SUM(W5:W6) -> 27800 | X7: =SUM(X5:X6) -> 0 | Y7: =SUM(Y5:Y6) -> 27800 | ... AM7: =SUM(AM5:AM6) -> 0
A8: HR Manager | W8: Finance Manager | AL8: Joint Director - Admin

Sheet Kindly Pay Salary Pay
E1: Teaching | J1: Admin | O1: Driver | T1: ECA Regular
T2: S. No | U2: Name | V2: Account Number | W2: Amount
E3: S. No | F3: Name | G3: Account Number | H3: Amount | J3: S. No | K3: Name | L3: Account Number | M3: Amount | O3: S. No | P3: Name | Q3: Account Number | R3: Amount | T3: =#REF! -> #REF! | U3: =#REF! -> #REF! | V3: =#REF! -> #REF! | W3: =#REF! -> #REF!
E4: =Academics!A5 -> 1 | F4: =Academics!B5 -> SUJATHA D/O SUBBURAM | G4: =Academics!AN5 -> 1750155000050628 | H4: =Academics!AJ5 -> 102700 | J4: =Admin!A5 -> 1 | K4: =Admin!B5 -> JOSEPHINE ANNE SHEEBHA ARULDASS | L4: =Admin!AN5 -> 1750062000000072 | M4: =Admin!AJ5 -> 67700 | O4: =Drivers!A5 -> 1 | P4: =Drivers!B5 -> KUMARAVEL MOOKKAIAH | Q4: =Drivers!AN5 -> 1750060000000508 | R4: =Drivers!AJ5 -> 22231 | T4: =#REF! -> #REF! | U4: =#REF! -> #REF! | V4: =#REF! -> #REF! | W4: =#REF! -> #REF!
E5: =Academics!A6 -> 2 | F5: =Academics!B6 -> A JAINCOL FATHIMA | G5: =Academics!AN6 -> 1750061000000064 | H5: =Academics!AJ6 -> 0 | J5: =Admin!A6 -> 2 | K5: =Admin!B6 -> Jeya Dharini Abinath | L5: =Admin!AN6 -> 0 | M5: =Admin!AJ6 -> 24500 | O5: =Drivers!A6 -> 2 | P5: =Drivers!B6 -> DURAIMURUGAN NAGARAJAN | Q5: =Drivers!AN6 -> 1750060000000522 | R5: =Drivers!AJ6 -> 18991 | T5: =#REF! -> #REF! | U5: =#REF! -> #REF! | V5: =#REF! -> #REF! | W5: =#REF! -> #REF!
E6: =Academics!#REF! -> #REF! | F6: =Academics!#REF! -> #REF! | G6: =Academics!#REF! -> #REF! | H6: =Academics!#REF! -> #REF! | J6: =Admin!#REF! -> #REF! | K6: =Admin!#REF! -> #REF! | L6: =Admin!#REF! -> #REF! | M6: =Admin!#REF! -> #REF! | O6: =Drivers!#REF! -> #REF! | P6: =Drivers!#REF! -> #REF! | Q6: =Drivers!#REF! -> #REF! | R6: =Drivers!#REF! -> #REF! | T6: =#REF! -> #REF! | U6: =#REF! -> #REF! | V6: =#REF! -> #REF! | W6: =#REF! -> #REF!
E7: =Academics!#REF! -> #REF! | F7: =Academics!#REF! -> #REF! | G7: =Academics!#REF! -> #REF! | H7: =Academics!#REF! -> #REF! | J7: =Admin!#REF! -> #REF! | K7: =Admin!#REF! -> #REF! | L7: =Admin!#REF! -> #REF! | M7: =Admin!#REF! -> #REF! | O7: =Drivers!#REF! -> #REF! | P7: =Drivers!#REF! -> #REF! | Q7: =Drivers!#REF! -> #REF! | R7: =Drivers!#REF! -> #REF! | T7: =#REF! -> #REF! | U7: =#REF! -> #REF! | V7: =#REF! -> #REF! | W7: =#REF! -> #REF!
E8: =Academics!#REF! -> #REF! | F8: =Academics!#REF! -> #REF! | G8: =Academics!#REF! -> #REF! | H8: =Academics!#REF! -> #REF! | J8: =Admin!#REF! -> #REF! | K8: =Admin!#REF! -> #REF! | L8: =Admin!#REF! -> #REF! | M8: =Admin!#REF! -> #REF! | O8: =Drivers!#REF! -> #REF! | P8: =Drivers!#REF! -> #REF! | Q8: =Drivers!#REF! -> #REF! | R8: =Drivers!#REF! -> #REF! | T8: =#REF! -> #REF! | U8: =#REF! -> #REF! | V8: =#REF! -> #REF! | W8: =#REF! -> #REF!
E9: =Academics!#REF! -> #REF! | F9: =Academics!#REF! -> #REF! | G9: =Academics!#REF! -> #REF! | H9: =Academics!#REF! -> #REF! | J9: =Admin!#REF! -> #REF! | K9: =Admin!#REF! -> #REF! | L9: =Admin!#REF! -> #REF! | M9: =Admin!#REF! -> #REF! | O9: =Drivers!#REF! -> #REF! | P9: =Drivers!#REF! -> #REF! | Q9: =Drivers!#REF! -> #REF! | R9: =Drivers!#REF! -> #REF! | T9: =#REF! -> #REF! | U9: =#REF! -> #REF! | V9: =#REF! -> #REF! | W9: =#REF! -> #REF!
E10: =Academics!#REF! -> #REF! | F10: =Academics!#REF! -> #REF! | G10: =Academics!#REF! -> #REF! | H10: =Academics!#REF! -> #REF! | J10: =Admin!#REF! -> #REF! | K10: =Admin!#REF! -> #REF! | L10: =Admin!#REF! -> #REF! | M10: =Admin!#REF! -> #REF! | O10: =Drivers!#REF! -> #REF! | P10: =Drivers!#REF! -> #REF! | Q10: =Drivers!#REF! -> #REF! | R10: =Drivers!#REF! -> #REF! | T10: =#REF! -> #REF! | U10: =#REF! -> #REF! | V10: =#REF! -> #REF! | W10: =#REF! -> #REF!
E11: =Academics!#REF! -> #REF! | F11: =Academics!#REF! -> #REF! | G11: =Academics!#REF! -> #REF! | H11: =Academics!#REF! -> #REF! | J11: =Admin!#REF! -> #REF! | K11: =Admin!#REF! -> #REF! | L11: =Admin!#REF! -> #REF! | M11: =Admin!#REF! -> #REF! | O11: =Drivers!#REF! -> #REF! | P11: =Drivers!#REF! -> #REF! | Q11: =Drivers!#REF! -> #REF! | R11: =Drivers!#REF! -> #REF! | T11: =#REF! -> #REF! | U11: =#REF! -> #REF! | V11: =#REF! -> #REF! | W11: =#REF! -> #REF!
E12: =Academics!#REF! -> #REF! | F12: =Academics!#REF! -> #REF! | G12: =Academics!#REF! -> #REF! | H12: =Academics!#REF! -> #REF! | J12: ='Relieved Admin'!#REF! -> #REF! | K12: ='Relieved Admin'!#REF! -> #REF! | L12: ='Relieved Admin'!#REF! -> #REF! | M12: ='Relieved Admin'!#REF! -> #REF! | O12: =Drivers!#REF! -> #REF! | P12: =Drivers!#REF! -> #REF! | Q12: =Drivers!#REF! -> #REF! | R12: =Drivers!#REF! -> #REF! | T12: =#REF! -> #REF! | U12: =#REF! -> #REF! | V12: =#REF! -> #REF! | W12: =#REF! -> #REF!
E13: =Academics!#REF! -> #REF! | F13: =Academics!#REF! -> #REF! | G13: =Academics!#REF! -> #REF! | H13: =Academics!#REF! -> #REF! | J13: =Admin!#REF! -> #REF! | K13: =Admin!#REF! -> #REF! | L13: =Admin!#REF! -> #REF! | M13: =Admin!#REF! -> #REF! | O13: =Drivers!#REF! -> #REF! | P13: =Drivers!#REF! -> #REF! | Q13: =Drivers!#REF! -> #REF! | R13: =Drivers!#REF! -> #REF! | T13: =#REF! -> #REF! | U13: =#REF! -> #REF! | V13: =#REF! -> #REF! | W13: =#REF! -> #REF!
E14: =Academics!#REF! -> #REF! | F14: =Academics!#REF! -> #REF! | G14: =Academics!#REF! -> #REF! | H14: =Academics!#REF! -> #REF! | J14: ='Relieved Admin'!A5 -> 1 | K14: ='Relieved Admin'!B5 -> DEEPIKA KANNAN | L14: ='Relieved Admin'!AN5 -> 1750060000000023 | M14: ='Relieved Admin'!AJ5 -> 6667 | O14: =Drivers!#REF! -> #REF! | P14: =Drivers!#REF! -> #REF! | Q14: =Drivers!#REF! -> #REF! | R14: =Drivers!#REF! -> #REF! | T14: =#REF! -> #REF! | U14: =#REF! -> #REF! | V14: =#REF! -> #REF! | W14: =#REF! -> #REF!
E15: =Academics!#REF! -> #REF! | F15: =Academics!#REF! -> #REF! | G15: =Academics!#REF! -> #REF! | H15: =Academics!#REF! -> #REF! | J15: =Admin!#REF! -> #REF! | K15: =Admin!#REF! -> #REF! | L15: =Admin!#REF! -> #REF! | M15: =Admin!#REF! -> #REF! | O15: =Drivers!#REF! -> #REF! | P15: =Drivers!#REF! -> #REF! | Q15: =Drivers!#REF! -> #REF! | R15: =Drivers!#REF! -> #REF!
E16: =Academics!#REF! -> #REF! | F16: =Academics!#REF! -> #REF! | G16: =Academics!#REF! -> #REF! | H16: =Academics!#REF! -> #REF! | J16: =Admin!#REF! -> #REF! | K16: =Admin!#REF! -> #REF! | L16: =Admin!#REF! -> #REF! | M16: =Admin!#REF! -> #REF! | O16: =Drivers!#REF! -> #REF! | P16: =Drivers!#REF! -> #REF! | Q16: =Drivers!#REF! -> #REF! | R16: =Drivers!#REF! -> #REF!
E17: =Academics!#REF! -> #REF! | F17: =Academics!#REF! -> #REF! | G17: =Academics!#REF! -> #REF! | H17: =Academics!#REF! -> #REF! | J17: =Admin!#REF! -> #REF! | K17: =Admin!#REF! -> #REF! | L17: =Admin!#REF! -> #REF! | M17: =Admin!#REF! -> #REF! | O17: ='Relieved Admin'!#REF! -> #REF! | P17: ='Relieved Admin'!#REF! -> #REF! | Q17: ='Relieved Admin'!#REF! -> #REF! | R17: ='Relieved Admin'!#REF! -> #REF!
E18: =Academics!#REF! -> #REF! | F18: =Academics!#REF! -> #REF! | G18: =Academics!#REF! -> #REF! | H18: =Academics!#REF! -> #REF! | J18: =Admin!#REF! -> #REF! | K18: =Admin!#REF! -> #REF! | L18: =Admin!#REF! -> #REF! | M18: =Admin!#REF! -> #REF! | O18: =Drivers!#REF! -> #REF! | P18: =Drivers!#REF! -> #REF! | Q18: =Drivers!#REF! -> #REF! | R18: =Drivers!#REF! -> #REF!
E19: =Academics!#REF! -> #REF! | F19: =Academics!#REF! -> #REF! | G19: =Academics!#REF! -> #REF! | H19: =Academics!#REF! -> #REF! | J19: =Admin!#REF! -> #REF! | K19: =Admin!#REF! -> #REF! | L19: =Admin!#REF! -> #REF! | M19: =Admin!#REF! -> #REF! | O19: ='Relieved Admin'!#REF! -> #REF! | P19: ='Relieved Admin'!#REF! -> #REF! | Q19: ='Relieved Admin'!#REF! -> #REF! | R19: ='Relieved Admin'!#REF! -> #REF!
E20: =Academics!#REF! -> #REF! | F20: =Academics!#REF! -> #REF! | G20: =Academics!#REF! -> #REF! | H20: =Academics!#REF! -> #REF! | J20: =Admin!#REF! -> #REF! | K20: =Admin!#REF! -> #REF! | L20: =Admin!#REF! -> #REF! | M20: =Admin!#REF! -> #REF! | O20: =Drivers!A7 -> TOTAL | R20: =Drivers!AJ7 -> 41222
E21: =Academics!#REF! -> #REF! | F21: =Academics!#REF! -> #REF! | G21: =Academics!#REF! -> #REF! | H21: =Academics!#REF! -> #REF! | J21: =Admin!#REF! -> #REF! | K21: =Admin!#REF! -> #REF! | L21: =Admin!#REF! -> #REF! | M21: =Admin!#REF! -> #REF!
E22: =Academics!#REF! -> #REF! | F22: =Academics!#REF! -> #REF! | G22: =Academics!#REF! -> #REF! | H22: =Academics!#REF! -> #REF! | J22: =Admin!#REF! -> #REF! | K22: =Admin!#REF! -> #REF! | L22: =Admin!#REF! -> #REF! | M22: =Admin!#REF! -> #REF!
E23: =Academics!#REF! -> #REF! | F23: =Academics!#REF! -> #REF! | G23: =Academics!#REF! -> #REF! | H23: =Academics!#REF! -> #REF! | J23: =Admin!#REF! -> #REF! | K23: =Admin!#REF! -> #REF! | L23: =Admin!#REF! -> #REF! | M23: =Admin!#REF! -> #REF!
E24: =Academics!#REF! -> #REF! | F24: =Academics!#REF! -> #REF! | G24: =Academics!#REF! -> #REF! | H24: =Academics!#REF! -> #REF! | J24: =Admin!#REF! -> #REF! | K24: =Admin!#REF! -> #REF! | L24: =Admin!#REF! -> #REF! | M24: =Admin!#REF! -> #REF!
E25: =Academics!#REF! -> #REF! | F25: =Academics!#REF! -> #REF! | G25: =Academics!#REF! -> #REF! | H25: =Academics!#REF! -> #REF! | J25: =Admin!#REF! -> #REF! | K25: =Admin!#REF! -> #REF! | L25: =Admin!#REF! -> #REF! | M25: =Admin!#REF! -> #REF!
E26: =Academics!#REF! -> #REF! | F26: =Academics!#REF! -> #REF! | G26: =Academics!#REF! -> #REF! | H26: =Academics!#REF! -> #REF! | J26: =Admin!#REF! -> #REF! | K26: =Admin!#REF! -> #REF! | L26: =Admin!#REF! -> #REF! | M26: =Admin!#REF! -> #REF! | O26: Conductors
E27: =Academics!#REF! -> #REF! | F27: =Academics!#REF! -> #REF! | G27: =Academics!#REF! -> #REF! | H27: =Academics!#REF! -> #REF! | J27: =Admin!#REF! -> #REF! | K27: =Admin!#REF! -> #REF! | L27: =Admin!#REF! -> #REF! | M27: =Admin!#REF! -> #REF! | O27: =Conductors!A5 -> 1 | P27: =Conductors!B5 -> SUNDARI JEYARAM | Q27: =Conductors!AN5 -> 1750059000000054 | R27: =Conductors!AJ5 -> 9400
E28: =Academics!#REF! -> #REF! | F28: =Academics!#REF! -> #REF! | G28: =Academics!#REF! -> #REF! | H28: =Academics!#REF! -> #REF! | J28: =Admin!#REF! -> #REF! | K28: =Admin!#REF! -> #REF! | L28: =Admin!#REF! -> #REF! | M28: =Admin!#REF! -> #REF! | O28: =Conductors!A6 -> 2 | P28: =Conductors!B6 -> S CHITRA | Q28: =Conductors!AN6 -> 1750059000000281 | R28: =Conductors!AJ6 -> 12106
E29: ='Relieved Academics'!#REF! -> #REF! | F29: ='Relieved Academics'!#REF! -> #REF! | G29: ='Relieved Academics'!#REF! -> #REF! | H29: ='Relieved Academics'!#REF! -> #REF! | J29: =Admin!#REF! -> #REF! | K29: =Admin!#REF! -> #REF! | L29: =Admin!#REF! -> #REF! | M29: =Admin!#REF! -> #REF! | O29: =Conductors!#REF! -> #REF! | P29: =Conductors!#REF! -> #REF! | Q29: =Conductors!#REF! -> #REF! | R29: =Conductors!#REF! -> #REF!
E30: =Academics!#REF! -> #REF! | F30: =Academics!#REF! -> #REF! | G30: =Academics!#REF! -> #REF! | H30: =Academics!#REF! -> #REF! | J30: =Admin!#REF! -> #REF! | K30: =Admin!#REF! -> #REF! | L30: =Admin!#REF! -> #REF! | M30: =Admin!#REF! -> #REF! | O30: =Conductors!#REF! -> #REF! | P30: =Conductors!#REF! -> #REF! | Q30: =Conductors!#REF! -> #REF! | R30: =Conductors!#REF! -> #REF!
E31: =Academics!#REF! -> #REF! | F31: =Academics!#REF! -> #REF! | G31: =Academics!#REF! -> #REF! | H31: =Academics!#REF! -> #REF! | J31: =Admin!#REF! -> #REF! | K31: =Admin!#REF! -> #REF! | L31: =Admin!#REF! -> #REF! | M31: =Admin!#REF! -> #REF! | O31: =Conductors!#REF! -> #REF! | P31: =Conductors!#REF! -> #REF! | Q31: =Conductors!#REF! -> #REF! | R31: =Conductors!#REF! -> #REF!
E32: =Academics!#REF! -> #REF! | F32: =Academics!#REF! -> #REF! | G32: =Academics!#REF! -> #REF! | H32: =Academics!#REF! -> #REF! | J32: =Admin!#REF! -> #REF! | K32: =Admin!#REF! -> #REF! | L32: =Admin!#REF! -> #REF! | M32: =Admin!#REF! -> #REF! | O32: =Conductors!#REF! -> #REF! | P32: =Conductors!#REF! -> #REF! | Q32: =Conductors!#REF! -> #REF! | R32: =Conductors!#REF! -> #REF!
E33: =Academics!#REF! -> #REF! | F33: =Academics!#REF! -> #REF! | G33: =Academics!#REF! -> #REF! | H33: =Academics!#REF! -> #REF! | J33: =Admin!#REF! -> #REF! | K33: =Admin!#REF! -> #REF! | L33: =Admin!#REF! -> #REF! | M33: =Admin!#REF! -> #REF! | O33: =Conductors!#REF! -> #REF! | P33: =Conductors!#REF! -> #REF! | Q33: =Conductors!#REF! -> #REF! | R33: =Conductors!#REF! -> #REF!
E34: =Academics!#REF! -> #REF! | F34: =Academics!#REF! -> #REF! | G34: =Academics!#REF! -> #REF! | H34: =Academics!#REF! -> #REF! | J34: =Admin!#REF! -> #REF! | K34: =Admin!#REF! -> #REF! | L34: =Admin!#REF! -> #REF! | M34: =Admin!#REF! -> #REF! | O34: =Conductors!#REF! -> #REF! | P34: =Conductors!#REF! -> #REF! | Q34: =Conductors!#REF! -> #REF! | R34: =Conductors!#REF! -> #REF!
E35: ='Relieved Academics'!#REF! -> #REF! | F35: ='Relieved Academics'!#REF! -> #REF! | G35: ='Relieved Academics'!#REF! -> #REF! | H35: ='Relieved Academics'!#REF! -> #REF! | J35: =Admin!#REF! -> #REF! | K35: =Admin!#REF! -> #REF! | L35: =Admin!#REF! -> #REF! | M35: =Admin!#REF! -> #REF! | O35: =Conductors!#REF! -> #REF! | P35: =Conductors!#REF! -> #REF! | Q35: =Conductors!#REF! -> #REF! | R35: =Conductors!#REF! -> #REF!
E36: =Academics!#REF! -> #REF! | F36: =Academics!#REF! -> #REF! | G36: =Academics!#REF! -> #REF! | H36: =Academics!#REF! -> #REF! | J36: =Admin!#REF! -> #REF! | K36: =Admin!#REF! -> #REF! | L36: =Admin!#REF! -> #REF! | M36: =Admin!#REF! -> #REF! | O36: =Conductors!#REF! -> #REF! | P36: =Conductors!#REF! -> #REF! | Q36: =Conductors!#REF! -> #REF! | R36: =Conductors!#REF! -> #REF!
E37: =Academics!#REF! -> #REF! | F37: =Academics!#REF! -> #REF! | G37: =Academics!#REF! -> #REF! | H37: =Academics!#REF! -> #REF! | J37: =Admin!#REF! -> #REF! | K37: =Admin!#REF! -> #REF! | L37: =Admin!#REF! -> #REF! | M37: =Admin!#REF! -> #REF! | O37: =Conductors!#REF! -> #REF! | P37: =Conductors!#REF! -> #REF! | Q37: =Conductors!#REF! -> #REF! | R37: =Conductors!#REF! -> #REF!
E38: =Academics!#REF! -> #REF! | F38: =Academics!#REF! -> #REF! | G38: =Academics!#REF! -> #REF! | H38: =Academics!#REF! -> #REF! | J38: =Admin!#REF! -> #REF! | K38: =Admin!#REF! -> #REF! | L38: =Admin!#REF! -> #REF! | M38: =Admin!#REF! -> #REF! | O38: =Conductors!A7 -> TOTAL | R38: =Conductors!AJ7 -> 21506
E39: =Academics!#REF! -> #REF! | F39: =Academics!#REF! -> #REF! | G39: =Academics!#REF! -> #REF! | H39: =Academics!#REF! -> #REF! | J39: ='Relieved Admin'!#REF! -> #REF! | K39: ='Relieved Admin'!#REF! -> #REF! | L39: ='Relieved Admin'!#REF! -> #REF! | M39: ='Relieved Admin'!#REF! -> #REF!
E40: =Academics!#REF! -> #REF! | F40: =Academics!#REF! -> #REF! | G40: =Academics!#REF! -> #REF! | H40: =Academics!#REF! -> #REF! | J40: =Admin!#REF! -> #REF! | K40: =Admin!#REF! -> #REF! | L40: =Admin!#REF! -> #REF! | M40: =Admin!#REF! -> #REF!
...

Sheet Hostel
A1: QUEEN MIRA INTERNATIONAL SCHOOL
A2: HOSTEL - SALARY STATEMENT JUNE 2026
A3: S.No | B3: Name | C3: Department | D3: Attendance | R3: Salary Advance / Loan Details | V3: Gross Salary | W3: Payable Gross Salary | X3: Other Allownace | Y3: Salary.Actuals [Gross Salary - Leave Deduction] | Z3: Salary per day [Gross salary / no of days that month] | AA3: Basic [45% of Gross Salary] | AB3: Deductions | AJ3: Net Salary | AK3: QMIS Contribution | AM3: Remarks
D4: Total working days | E4: Lates. Actuals | F4: Lates. Leave [Exceeding lates conversions count] | G4: Final Lates after deducting exceeding Late leaves | H4: Permissions.Actuals | I4: Exceeding Permissions taken for this month | J4: Proper Permissions | K4: Proper Casual Leave already taken for this year till date | L4: Proper Casual Leave taken for this month | M4: Exceeding Casual Leave taken for this month / Memo issued | N4: Absent / Suspension.Actuals | O4: Gardening / Other Leave | P4: Total Leave days.Actuals | Q4: Loss of Pay Days | R4: Total Loan Amount | S4: Amount already paid | T4: Amount to be paid for this month | U4: Remaining Loan Amount | AB4: Leave / Absent / Permission Leave / Late Leave | AC4: Not Punched Days | AD4: Not Punched LOP | AE4: Salary Advance / Loan | AF4: Special Deductions [Telephone Bill + Laptop + Uniform + Trainings etc] | AG4: PF [12% of Basic Salary] | AH4: ESI [0.75% of Salary.Actuals] | AI4: Total | AK4: PF [13.01% of Basic Salary] | AL4: ESI [3.25% of Salary.Actuals]
A5: 1 | B5: Pangajam | C5: Chef | D5: 30 | E5: 0 | F5: =IF((E5/3)>=1,TRUNC(E5/3,0),0) -> 0 | G5: =E5-F5*3 -> 0 | H5: 0 | I5: =IF(H5<2,H5,H5-2) -> 0 | J5: =H5-I5 -> 0 | K5: 0 | L5: 0 | M5: 0 | N5: 0 | O5: 0 | P5: =L5+M5+N5+O5 -> 0 | Q5: =(F5*0.5)+(I5*0.5)+L5+(N5*2)+M5 -> 0 | T5: 0 | U5: =R5-(S5+T5) -> 0 | V5: 26000 | W5: =V5 -> 26000 | X5: 0 | Y5: =V5-AB5 -> 26000 | Z5: =(V5+X5)/31 -> 838.70968 | AA5: =V5*45% -> 11700 | AB5: =Q5*Z5 -> 0 | AD5: =(AC5)*Z5 -> 0 | AE5: =T5 -> 0 | AG5: 0 | AH5: 0 | AI5: =SUM(AB5,AD5:AH5) -> 0 | AJ5: =ROUND(SUM(W5:X5)-AI5,0) -> 26000 | AK5: 0 | AL5: 0 | AN5: 1750060000001345
A6: 2 | B6: Meena | C6: Chef | D6: 30 | E6: 0 | F6: =IF((E6/3)>=1,TRUNC(E6/3,0),0) -> 0 | G6: =E6-F6*3 -> 0 | H6: 0 | I6: =IF(H6<2,H6,H6-2) -> 0 | J6: =H6-I6 -> 0 | K6: 0 | L6: 0 | M6: 0 | N6: 0 | O6: 0 | P6: =L6+M6+N6+O6 -> 0 | Q6: =(F6*0.5)+(I6*0.5)+L6+(N6*2)+M6 -> 0 | T6: 0 | U6: =R6-(S6+T6) -> 0 | V6: 7000 | W6: =V6 -> 7000 | X6: 0 | Y6: =V6-AB6 -> 7000 | Z6: =(V6+X6)/31 -> 225.80645 | AA6: =V6*45% -> 3150 | AB6: =Q6*Z6 -> 0 | AD6: =(AC6)*Z6 -> 0 | AE6: =T6 -> 0 | AG6: 0 | AH6: 0 | AI6: =SUM(AB6,AD6:AH6) -> 0 | AJ6: =ROUND(SUM(W6:X6)-AI6,0) -> 7000 | AK6: 0 | AL6: 0 | AN6: 1750060000002123
A7: 3 | B7: AARTHY SELVAM | C7: House Keeping Supervisor | D7: 30 | E7: 0 | F7: =IF((E7/3)>=1,TRUNC(E7/3,0),0) -> 0 | G7: =E7-F7*3 -> 0 | H7: 0 | I7: =IF(H7<1,H7,H7-1) -> 0 | J7: =H7-I7 -> 0 | K7: 0 | L7: 0 | M7: 0 | N7: 0 | O7: 0 | P7: =L7+M7+N7+O7 -> 0 | Q7: =(F7*0.5)+(I7*0.5)+M7+(N7*2) -> 0 | U7: =R7-(S7+T7) -> 0 | V7: 7500 | W7: =V7 -> 7500 | X7: 0 | Y7: =V7-AB7 -> 7500 | Z7: =(V7+X7)/31 -> 241.93548 | AA7: =V7*45% -> 3375 | AB7: =Q7*Z7 -> 0 | AD7: =(AC7)*Z7 -> 0 | AE7: =T7 -> 0 | AF7: 0 | AG7: 0 | AH7: 0 | AI7: =SUM(AB7,AD7:AH7) -> 0 | AJ7: =ROUND(SUM(W7:X7)-AI7,0) -> 7500 | AK7: 0 | AL7: 0 | AN7: 1750060000001274
A8: TOTAL | R8: =SUM(R5:R7) -> 0 | S8: =SUM(S5:S7) -> 0 | T8: =SUM(T5:T7) -> 0 | U8: =SUM(U5:U7) -> 0 | V8: =SUM(V5:V7) -> 40500 | W8: =SUM(W5:W7) -> 40500 | X8: =SUM(X5:X7) -> 0 | Y8: =SUM(Y5:Y7) -> 40500 | ... AL8: =SUM(AL5:AL7) -> 0
A9: HR Manager | V9: Finance Manager | AL9: Director Academics
R15: =(G15*0.5)+(J15*0.5)+N15+(O15*2) -> 0

Sheet ECA 
A1: QUEEN MIRA INTERNATIONAL SCHOOL
A2: ECA REGULAR - SALARY STATEMENT JUNE 2026
A3: ECA Staff - Regular Salary
A4: S.No | B4: Name | C4: Department | D4: Gross Salary | E4: Total No.of Classes | F4: No.of days Leave | G4: Advance Total | H4: Already Paid | I4: Pending Deduction | J4: Current Month deduction | K4: Leave Deduction Amt | L4: Other Deductions | M4: Net Salary | N4: Remarks
A5: 1 | B5: R BALACHANDER | C5: Western Dance | D5: 20000 | E5: 7 | F5: 1 | G5: 0 | I5: 0 | J5: 0 | K5: =D5/8*F5 -> 2500 | L5: 0 | M5: =ROUND(D5-J5-K5-L5,0) -> 17500 | N5: Per day salary calculated= Gross salary / No of classes-Vacation Holiday | O5: 1750060000000106
A6: 2 | B6: ARAVINDHU PASHWAN VELAYUTHAM | C6: Guitar | D6: 12500 | E6: 1 | F6: 1 | G6: 0 | I6: 0 | J6: 0 | K6: =D6/8*F6 -> 1562.5 | L6: 0 | M6: =ROUND(D6-J6-K6-L6,0) -> 10938 | N6: Per day salary calculated= Gross salary / No of classes-Vacation Holiday | O6: 1750061000000241
A7: 3 | B7: J RAJA / Chandra | C7: Silambam | D7: 13000 | E7: 7 | F7: 0 | G7: 0 | I7: 0 | J7: 0 | K7: =D7/8*F7 -> 0 | L7: 0 | M7: =ROUND(D7-J7-K7-L7,0) -> 13000 | N7: Per day salary calculated= Gross salary / No of classes-Vacation Holiday | O7: 1750060000001298
A8: 4 | B8: J RAJA / Amutheswaran | C8: Karate | D8: 12000 | E8: 7 | F8: 0 | G8: 0 | I8: 0 | J8: 0 | K8: =D8/8*F8 -> 0 | L8: 0 | M8: =ROUND(D8-J8-K8-L8,0) -> 12000 | N8: Per day salary calculated= Gross salary / No of classes-Vacation Holiday | O8: 1750060000001298
A9: 5 | B9: PRAKASHKUMAR BALAJI | C9: Taekwondo | D9: 13000 | E9: 7 | F9: 0 | G9: 0 | I9: 0 | J9: 0 | K9: =D9/8*F9 -> 0 | L9: 0 | M9: =ROUND(D9-J9-K9-L9,0) -> 13000 | N9: Per day salary calculated= Gross salary / No of classes-Vacation Holiday - | O9: 1750061000000135
A10: 6 | B10: PRAKASHKUMAR BALAJI | C10: Yoga | D10: 11000 | E10: 8 | F10: 0 | G10: 0 | I10: 0 | J10: 0 | K10: =D10/8*F10 -> 0 | L10: 0 | M10: =ROUND(D10-J10-K10-L10,0) -> 11000 | N10: Per day salary calculated= Gross salary / No of classes-Vacation Holiday | O10: 1750061000000135
A11: 7 | B11: PRABAKARAN PANDI | C11: Kung Fu | D11: 14000 | E11: 7 | F11: 0 | G11: 0 | I11: 0 | J11: 0 | K11: =D11/8*F11 -> 0 | L11: 0 | M11: =ROUND(D11-J11-K11-L11,0) -> 14000 | N11: Per day salary calculated= Gross salary / No of classes-Vacation Holiday | O11: 1750060000000132
A12: 8 | B12: HARIPRASATH JAYAKUMAR | C12: Drums | D12: 12000 | E12: 8 | F12: 0 | G12: 0 | I12: 0 | J12: 0 | K12: =D12/8*F12 -> 0 | L12: 0 | M12: =ROUND(D12-J12-K12-L12,0) -> 12000 | N12: Per day salary calculated= Gross salary / No of classes-Vacation Holiday | O12: 1750061000000265
A13: 9 | B13: RAJA CHINNASAMI | C13: Key Board | D13: 17000 | E13: 8 | F13: 0 | G13: 0 | I13: 0 | J13: 0 | K13: =D13/8*F13 -> 0 | L13: 0 | M13: =ROUND(D13-J13-K13-L13,0) -> 17000 | N13: Per day salary calculated= Gross salary / No of classes-Vacation Holiday | O13: 1750061000000232
A14: 10 | B14: JEYA SHREE R | C14: Classical Dance | D14: 20500 | E14: 8 | F14: 0 | G14: 0 | I14: 0 | J14: 0 | K14: =D14/8*F14 -> 0 | L14: 0 | M14: =ROUND(D14-J14-K14-L14,0) -> 20500 | N14: Per day salary calculated= Gross salary / No of classes-Vacation Holiday | O14: 1750060000000850
A15: 11 | B15: SUBAHARI | C15: Carnatic Music | D15: 18000 | E15: 8 | F15: 0 | G15: 0 | I15: 0 | J15: 0 | K15: =D15/8*F15 -> 0 | L15: 0 | M15: =ROUND(D15-J15-K15-L15,0) -> 18000 | N15: Per day salary calculated= Gross salary / No of classes-Vacation Holiday | O15: 1750061000000253
A16: 12 | B16: DANIEL MERWIN SELVARAJ | C16: Skatting Coach | D16: 26000 | E16: 19 | F16: 0 | G16: 0 | I16: 0 | J16: 0 | K16: =D16/31*F16 -> 0 | L16: 0 | M16: =ROUND(D16-J16-K16-L16,0) -> 26000 | N16: Per day salary calculated= Gross salary / No of days 30 or 31-Vacation Holiday | O16: 1750061000000289
A17: 13 | B17: K KEERTHIGA | C17: Arts and Craft | D17: 12000 | E17: 6 | F17: 1 | G17: 0 | I17: 0 | J17: 0 | K17: =D17/31*F17 -> 387.09677 | L17: 0 | M17: =ROUND(D17-J17-K17-L17,0) -> 11613 | N17: No salary for April'2026 - No classes assigned. Per day salary calculated= Gross salary / No of days 30 or 31-Vacation Holiday | O17: '1750060000001300
A18: 14 | B18: ARUNKANTH MURUGAN | C18: Table Tennis | D18: 20000 | E18: 18 | F18: 0 | G18: 0 | I18: 0 | J18: 0 | K18: =D18/31*F18 -> 0 | L18: 0 | M18: =ROUND(D18-J18-K18-L18,0) -> 20000 | N18: Per day salary calculated= Gross salary / No of days 30 or 31-Vacation Holiday | O18: 1750061000000348
A19: Total | D19: =SUM(D5:D18) -> 221000 | E19: =SUM(E5:E18) -> 119 | F19: =SUM(F5:F18) -> 3 | G19: =SUM(G5:G18) -> 0 | H19: =SUM(H5:H18) -> 0 | I19: =SUM(I5:I18) -> 0 | J19: =SUM(J5:J18) -> 0 | K19: =SUM(K5:K18) -> 4449.5968 | ... M19: =SUM(M5:M18) -> 216551 | XFD19: =SUM(D19:XFC19) -> 442122.6
A20: HR Manager Finance Manager Director Academics

Sheet Part time academic
A1: QUEEN MIRA INTERNATIONAL SCHOOL
A2: Part Time Academics - SALARY STATEMENT JUNE 2026
A3: S.No | B3: Name | C3: Department | D3: Gross Salary | E3: Classes taken / Days reported | F3: Per Day Salary | G3: No. of Leaves | H3: Special Deductions | I3: Leave Deductions | J3: Net Salary | K3: Remarks
A4: 1 | B4: Chandrashekaran | C4: Chemistry | D4: =E4*1600 -> 57600 | E4: 36 | F4: =D4/30 -> 1920 | G4: 0 | H4: 0 | I4: =F4*G4 -> 0 | J4: =ROUND(D4-I4-H4,0) -> 57600 | K4: 1600 Per hour. / Due to Emergncy Salary Given on 30/06/2026(54000) | L4: Cash
A5: 3 | B5: Thirubuvan | C5: Physics | D5: =E5*1200 -> 44592 | E5: 37.16 | F5: =D5/30 -> 1486.4 | G5: 0 | H5: 0 | I5: =F5*G5 -> 0 | J5: =ROUND(D5-I5-H5,0) -> 44592 | K5: 1200 Per hour. | L5: 1750061000000419
A6: 4 | B6: Naveen Kumar | C6: French | D6: =20000 -> 20000 | E6: 20 | F6: =D6/30 -> 666.66667 | G6: 1 | I6: =F6*G6 -> 666.66667 | J6: =ROUND(D6-I6-H6,0) -> 19333 | K6: Leave on 17/06/2026 | L6: 1750060000001215
A7: 5 | B7: KALPANA KARTHIK S | C7: Curriculum Advisor & PGT Economics | D7: 36000 | E7: 27 | F7: =D7/30 -> 1200 | I7: =F7*G7 -> 0 | J7: =ROUND(D7-I7-H7,0) -> 36000 | K7: Gross Salary Rs. 36,000. she worked Full day on 13/06/2026 ,15/06/2026, 20/06/2026,22/06/2026, 29/06/2026 | L7: 1750062000000034
A8: 6 | B8: MATCHIPIRAI MALIKA KATHEROLI | C8: Hindi | D8: 44000 | E8: 30 | F8: =D8/30 -> 1466.6667 | G8: 0 | I8: =F8*G8 -> 0 | J8: =ROUND(D8-I8-H8,0) -> 44000 | L8: 1750061000000312
A9: 7 | B9: I PRADEEP CHRISTOPHER | C9: French | D9: 29000 | E9: 12 | F9: =D9/30 -> 966.66667 | I9: =F9*G9 -> 0 | J9: =ROUND(D9-I9-H9,0) -> 29000 | L9: 1750061000000362
A10: 8 | B10: DHARANI W/O SRINIVAS | C10: School Counsellor | D10: 46000 | E10: 11 | F10: =D10/30 -> 1533.3333 | I10: =F10*G10 -> 0 | J10: =ROUND(D10-I10-H10,0) -> 46000 | L10: 1750061000000220
A11: 9 | B11: Jeyabal J | C11: Creative space | D11: =450*E11 -> 2700 | E11: 6 | F11: =D11/30 -> 90 | G11: 0 | I11: =F11*G11 -> 0 | J11: =ROUND(D11-I11-H11,0) -> 2700 | K11: (Actual classes to be planned 8 days * 8 periods = 64 periods for each) Per period Rs 450 No Class in April 2026 | L11: 1105155000093166
A12: 11 | B12: Niveth Oliviya | C12: Creative space | D12: =450*E12 -> 0 | E12: 0 | F12: =D12/30 -> 0 | G12: 0 | I12: =F12*G12 -> 0 | J12: =ROUND(D12-I12-H12,0) -> 0 | L12: 1750060000001203
A13: 12 | B13: Anushkumar | C13: Creative space Tuesday and Friday | D13: =20000/9*3 -> 6666.6667 | E13: 2 | F13: =D13/9 -> 740.74074 | G13: 0 | I13: =F13*G13 -> 0 | J13: =ROUND(D13-I13-H13,0) -> 6667 | K13: DOJ 23/06/26 / 1 Holiday
A14: Total | D14: =SUM(D4:D13) -> 286558.67 | E14: =SUM(E4:E13) -> 181.16 | F14: =SUM(F4:F12) -> 9329.7333 | G14: =SUM(G4:G12) -> 1 | H14: =SUM(H4:H12) -> 0 | I14: =SUM(I4:I12) -> 666.66667 | J14: =SUM(J4:J12) -> 279225
A15: HR Manager | E15: Finance Manager | K15: Director Academics

Sheet Theni - Upparpatti
A1: QUEEN MIRA INTERNATIONAL SCHOOL
A2: THENI UPPARPATTI - SALARY STATEMENT JUNE 2026
A3: S.No | B3: Name | C3: Department | D3: Attendance | R3: Salary Advance / Loan Details | V3: Gross Salary | W3: Payable Gross Salary | X3: Other Allownace | Y3: Salary.Actuals [Gross Salary - Leave Deduction] | Z3: Salary per day [Gross salary / no of days that month] | AA3: Basic [45% of Gross Salary] | AB3: Deductions | AJ3: Net Salary | AK3: QMIS Contribution | AM3: Remarks
